Workbook
Name ScenarioSwitch: Input!$D$6

Sheet Cover
C4: DCF Modeling | L4: CONFIDENTIAL
C7: Table of Contents | H7: Model Checks & Circularity
C9: Ouput | H9: Incorrect Date Set for Valuation? | L9: =Input!F200 -> 0
C10: Input | H10: Incorrect Date Set for First Cash Flow? | L10: =Input!F201 -> 0
C11: Model | H11: Terminal Growth Rate Greater Than or Equal To WACC? | L11: =Input!F212 -> 0
H12: Unused Tax Losses Remaining? (Levered Schedule) | L12: =Model!D127 -> 0
H13: Unused Tax Losses Remaining? (Unlevered Schedule) | L13: =Model!D165 -> 0
C14: Model Guide | H14: Two UFCF Methods Different? | L14: =IF(SUM(Model!I226:N226)>0,1,0) -> 0
H15: Balance Sheet Unbalanced? | L15: =IF(ROUND(SUMPRODUCT(ABS(Model!$F$580:$M$580)),2)=0,0,1) -> 0
C16: Adjustable Input | D16: (Grey Cell)
C17: Hardcode | D17: (Blue Font)
C18: Formula | D18: (Black Font)
O19: Do Not
C20: Model Circularity | O20: Delete
C22: Circularity Switch | D22: 0 | O22: Circularity
O23: 1
C24: =IF($D$22=1,"This model now has the circularity turned on. Please confirm the Excel settings below","") | O24: 0
C25: =IF($D$22=1,"PC","") | D25: =IF($D$22=1,"File - Options - Formulas - Check the box on the top-right labeled 'Enable iterative calculation'.","")
C26: =IF($D$22=1,"Mac","") | D26: =IF($D$22=1,"Excel - Preferences - Calculation - Check the box near the bottom labeled 'Use iterative calculation'.","")
C28: DISCLAIMER & NOTICE OF INTENT
C29: 1. Independent Portfolio Project: This financial model and dashboard were prepared solely by the author, in a personal capacity, to demonstrate
C30: skills in financial modeling and financial statement analysis. They do not reflect the views of any employer.
C31: 2. Public Data Sources: Historical figures are drawn from publicly available sources (Nestlé Investor Relations / Annual Reports). Forecasts and
C32: scenarios (Best / Base / Worst) are the author's own illustrative assumptions, not forecasts issued by Nestlé.
C33: 3. No Affiliation: This project is not affiliated with, authorized by, or endorsed by Nestlé S.A. Nestlé and related names and marks are the
C34: property of their respective owners and are used for identification only.
C35: 4. No Advice: Nothing herein constitutes investment advice, equity research, or a recommendation to buy or sell any security.

Sheet Output
B2: ="Nestlé S.A. | CHF millions | Scenario: "&INDEX(Input!$B$12:$B$14,Input!$D$6) -> Nestlé S.A. | CHF millions | Scenario: Base Case
B4: Dashboard: Perpetuity Method
B6: =Input!$B$8 -> All figures in CHF millions unless stated
B8: Driver Switch: | D8: 2
D10: Main Outputs 1 | L10: Selected Inputs
E12: Enterprise | F12: Equity | G12: Equity | H12: Premium | P12: Step
E13: Value | F13: Value | G13: Per Share | H13: (Discount) | L13: Terminal Growth Rate | O13: =Input!$F$209 -> 0.015 | P13: 0.005
E14: =Model!$G$277 -> 270962.42 | L14: WACC | O14: =Input!$N$257 -> 0.050865749 | P14: 0.005
D15: 1 | E15: 425996.36 | F15: =E15-$O$15 -> 405609.88 | G15: =F15/$O$16 -> 157.64084 | H15: =G15/$O$17-1 -> 1.1122986 | L15: Net Debt & Other Claims | N15: (at Val. Date) | O15: =Input!$N$196+Input!$N$197+Input!$N$199-Input!$N$198 -> 20386.48
D16: 2 | E16: 270962.42 | F16: =E16-$O$15 -> 250575.94 | G16: =F16/$O$16 -> 97.386683 | H16: =G16/$O$17-1 -> 0.30492674 | L16: Shares Outstanding | N16: (FD mm) | O16: =Input!$F$207 -> 2573
D17: 3 | E17: 163554.22 | F17: =E17-$O$15 -> 143167.74 | G17: =F17/$O$16 -> 55.642339 | H17: =G17/$O$17-1 -> -0.25442397 | L17: Current Stock Price | N17: (CHF/sh) | O17: =Input!$F$208 -> 74.63
D21: Enterprise Value 1 | L21: Equity Value per Share
D23: Terminal Growth Rate | L23: Terminal Growth Rate
C24: =Model!$G$277 -> 270962.42 | D24: =E24-$P$13 -> 0.005 | E24: =F24-$P$13 -> 0.01 | F24: =Input!$F$209 -> 0.015 | G24: =F24+$P$13 -> 0.02 | H24: =G24+$P$13 -> 0.025 | L24: =D24 -> 0.005 | M24: =E24 -> 0.01 | N24: =F24 -> 0.015 | O24: =G24 -> 0.02 | P24: =H24 -> 0.025
B25: WACC | C25: =C26-$P$14 -> 0.040865749 | D25: 280829.01 | E25: 319714.32 | F25: 373633.14 | G25: 453392.79 | H25: 583424.04 | J25: WACC | K25: =C25 -> 0.040865749 | L25: =D38/$O$16 -> 101.22135 | M25: =E38/$O$16 -> 116.33418 | N25: =F38/$O$16 -> 137.2898 | O25: =G38/$O$16 -> 168.2885 | P25: =H38/$O$16 -> 218.82533
C26: =C27-$P$14 -> 0.045865749 | D26: 247025.88 | E26: 275837.8 | F26: 313984.33 | G26: 366878.74 | H26: 445123.03 | K26: =C26 -> 0.045865749 | L26: =D39/$O$16 -> 88.083714 | M26: =E39/$O$16 -> 99.28151 | N26: =F39/$O$16 -> 114.10721 | O26: =G39/$O$16 -> 134.6647 | P26: =H39/$O$16 -> 165.07445
C27: =Input!$F$211 -> 0.050865749 | D27: 220591.2 | E27: 242695.3 | F27: 270962.42 | G27: 308387.61 | H27: 360281.83 | K27: =C27 -> 0.050865749 | L27: =D40/$O$16 -> 77.80984 | M27: =E40/$O$16 -> 86.40063 | N27: =F40/$O$16 -> 97.386683 | O27: =G40/$O$16 -> 111.93204 | P27: =H40/$O$16 -> 132.1008
C28: =C27+$P$14 -> 0.055865749 | D28: 199352.09 | E28: 216776.39 | F28: 238464.49 | G28: 266199.6 | H28: 302920.44 | K28: =C28 -> 0.055865749 | L28: =D41/$O$16 -> 69.555231 | M28: =E41/$O$16 -> 76.32721 | N28: =F41/$O$16 -> 84.756318 | O28: =G41/$O$16 -> 95.535608 | P28: =H41/$O$16 -> 109.80721
C29: =C28+$P$14 -> 0.060865749 | D29: 181913.56 | E29: 195950.93 | F29: 213048.83 | G29: 234330.65 | H29: 261546.22 | K29: =C29 -> 0.060865749 | L29: =D42/$O$16 -> 62.777721 | M29: =E42/$O$16 -> 68.233364 | N29: =F42/$O$16 -> 74.878488 | O29: =G42/$O$16 -> 83.149699 | P29: =H42/$O$16 -> 93.727067
D34: Equity Value | L34: Premium (Discount) to Stock Price
D36: Terminal Growth Rate | L36: Terminal Growth Rate
D37: =D24 -> 0.005 | E37: =E24 -> 0.01 | F37: =F24 -> 0.015 | G37: =G24 -> 0.02 | H37: =H24 -> 0.025 | L37: =D37 -> 0.005 | M37: =E37 -> 0.01 | N37: =F37 -> 0.015 | O37: =G37 -> 0.02 | P37: =H37 -> 0.025
B38: WACC | C38: =C25 -> 0.040865749 | D38: =D25-$O$15 -> 260442.53 | E38: =E25-$O$15 -> 299327.84 | F38: =F25-$O$15 -> 353246.66 | G38: =G25-$O$15 -> 433006.31 | H38: =H25-$O$15 -> 563037.56 | J38: WACC | K38: =C38 -> 0.040865749 | L38: =L25/$O$17-1 -> 0.35630909 | M38: =M25/$O$17-1 -> 0.55881249 | N38: =N25/$O$17-1 -> 0.83960608 | O38: =O25/$O$17-1 -> 1.2549712 | P38: =P25/$O$17-1 -> 1.9321362
C39: =C26 -> 0.045865749 | D39: =D26-$O$15 -> 226639.4 | E39: =E26-$O$15 -> 255451.32 | F39: =F26-$O$15 -> 293597.85 | G39: =G26-$O$15 -> 346492.26 | H39: =H26-$O$15 -> 424736.55 | K39: =C39 -> 0.045865749 | L39: =L26/$O$17-1 -> 0.18027219 | M39: =M26/$O$17-1 -> 0.33031635 | N39: =N26/$O$17-1 -> 0.52897238 | O39: =O26/$O$17-1 -> 0.80443114 | P39: =P26/$O$17-1 -> 1.2119047
C40: =C27 -> 0.050865749 | D40: =D27-$O$15 -> 200204.72 | E40: =E27-$O$15 -> 222308.82 | F40: =F27-$O$15 -> 250575.94 | G40: =G27-$O$15 -> 288001.13 | H40: =H27-$O$15 -> 339895.35 | K40: =C40 -> 0.050865749 | L40: =L27/$O$17-1 -> 0.042608071 | M40: =M27/$O$17-1 -> 0.15771982 | N40: =N27/$O$17-1 -> 0.30492674 | O40: =O27/$O$17-1 -> 0.49982631 | P40: =P27/$O$17-1 -> 0.77007633
C41: =C28 -> 0.055865749 | D41: =D28-$O$15 -> 178965.61 | E41: =E28-$O$15 -> 196389.91 | F41: =F28-$O$15 -> 218078.01 | G41: =G28-$O$15 -> 245813.12 | H41: =H28-$O$15 -> 282533.96 | K41: =C41 -> 0.055865749 | L41: =L28/$O$17-1 -> -0.067999045 | M41: =M28/$O$17-1 -> 0.022741663 | N41: =N28/$O$17-1 -> 0.13568696 | O41: =O28/$O$17-1 -> 0.28012338 | P41: =P28/$O$17-1 -> 0.47135486
C42: =C29 -> 0.060865749 | D42: =D29-$O$15 -> 161527.08 | E42: =E29-$O$15 -> 175564.45 | F42: =F29-$O$15 -> 192662.35 | G42: =G29-$O$15 -> 213944.17 | H42: =H29-$O$15 -> 241159.74 | K42: =C42 -> 0.060865749 | L42: =L29/$O$17-1 -> -0.15881386 | M42: =M29/$O$17-1 -> -0.085711318 | N42: =N29/$O$17-1 -> 0.0033296025 | O42: =O29/$O$17-1 -> 0.11415917 | P42: =P29/$O$17-1 -> 0.25588995
P44: These tables require the workbook calculation to be set to automatic to update.
B48: Dashboard: Multiple Method
B50: =Input!$B$8 -> All figures in CHF millions unless stated
B51: =CONCATENATE("Model Running: ",INDEX(Input!$B$12:$B$14,Input!$D$6)," Drivers") -> Model Running: Base Case Drivers
D54: Main Outputs 1 | L54: Selected Inputs
E56: Enterprise | F56: Equity | G56: Equity | H56: Premium | P56: Step
E57: Value | F57: Value | G57: Per Share | H57: (Discount) | L57: Terminal Multiple | O57: =Input!$F$210 -> 13.5 | P57: 0.5
E58: =Model!$G$325 -> 232364.58 | L58: WACC | O58: =Input!$N$257 -> 0.050865749 | P58: 0.005
D59: 1 | E59: 303567.82 | F59: =E59-$O$59 -> 283181.34 | G59: =F59/$O$60 -> 110.05882 | H59: =G59/$O$61-1 -> 0.47472625 | L59: Net Debt & Other Claims | N59: (at Val. Date) | O59: =Input!$N$196+Input!$N$197+Input!$N$199-Input!$N$198 -> 20386.48
D60: 2 | E60: 232364.58 | F60: =E60-$O$59 -> 211978.1 | G60: =F60/$O$60 -> 82.385579 | H60: =G60/$O$61-1 -> 0.1039204 | L60: Shares Outstanding | N60: (FD mm) | O60: =Input!$F$207 -> 2573
D61: 3 | E61: 168418.31 | F61: =E61-$O$59 -> 148031.83 | G61: =F61/$O$60 -> 57.532777 | H61: =G61/$O$61-1 -> -0.22909317 | L61: Current Stock Price | N61: (CHF/sh) | O61: =Input!$F$208 -> 74.63
D65: Enterprise Value 1 | L65: Equity Value per Share
D67: Terminal Multiple | L67: Terminal Multiple
...

Sheet Input
B2: ="Nestlé S.A. | CHF millions | Scenario: "&INDEX(Input!$B$12:$B$14,Input!$D$6) -> Nestlé S.A. | CHF millions | Scenario: Base Case | I2: =F173 -> 2026 | J2: =I2+1 -> 2027 | K2: =J2+1 -> 2028 | L2: =K2+1 -> 2029 | M2: =L2+1 -> 2030 | N2: Term | P2: Justification / Basis of assumption
B4: Growth & Margin Drivers
C6: Model Running: | D6: =Output!$D$8 -> 2
B8: All figures in CHF millions unless stated | I8: =I$2 -> 2026 | J8: =J$2 -> 2027 | K8: =K$2 -> 2028 | L8: =L$2 -> 2029 | M8: =M$2 -> 2030 | N8: =N$2 -> Term
B10: Sales growth, % YoY | I10: =INDEX(I12:I14,$D$6) -> 0.005 | J10: =INDEX(J12:J14,$D$6) -> 0.015 | K10: =INDEX(K12:K14,$D$6) -> 0.005 | L10: =INDEX(L12:L14,$D$6) -> 0.02 | M10: =INDEX(M12:M14,$D$6) -> 0.028 | N10: =INDEX(N12:N14,$D$6) -> 0.015
B12: Best Case | I12: 0.025 | J12: 0.035 | K12: 0.04 | L12: 0.045 | M12: 0.05 | N12: 0.02 | P12: Best Case: reported sales growth converges toward the organic growth guidance (3–4% for 2026) as the c.3% FX headwind from a strong CHF and the 2025–26 portfolio exits (Waters JV, VMS, ice cream) roll off, building to 5% by 2030. Source: Nestlé H1 2026 results and FY2026 guidance. | Term (N): 2.0% perpetual growth in CHF – upper end of the long-run CHF nominal range (c.1% inflation + c.1% real volume).
B13: Base Case | I13: 0.005 | J13: 0.015 | K13: 0.005 | L13: 0.02 | M13: 0.028 | N13: 0.015 | P13: Base Case: 2026 +0.5% = organic growth guidance of 3–4% less a c.3% FX headwind at spot rates (H1 2026 guidance); 2027 +1.5% as FX normalises; 2028 slows under an assumed mild global slowdown; 2029–30 returns toward the organic trend (2.0–2.8%). The Waters deconsolidation into the Peranel JV (FY2025 sales CHF 3.5bn, closing H1 2027) is not modelled separately and would lower 2027 reported sales by up to c.4pp. | Term (N): 1.5% perpetual growth in CHF = c.0.5–1.0% long-run CHF inflation (SNB target 0–2%) plus c.1% real volume, net of the structural drag from CHF appreciation on translated sales. Feeds the Gordon-growth terminal value via cell F209.
B14: Worst Case | I14: -0.015 | J14: -0.01 | K14: -0.055 | L14: -0.03 | M14: 0.005 | N14: 0.01 | P14: Worst Case: a demand and macro shock in 2028–29 (–5.5% and –3.0%), sized on the roughly ten-year cadence of past global stress events (1998, 2008, 2020). Consumer staples are assumed to decline less than cyclical sectors, with stabilisation in 2030. | Term (N): 1.0% – persistent CHF strength and a low-volume staples environment.
B17: Other revenue, % of sales | I17: =INDEX(I19:I21,$D$6) -> 0.0042 | J17: =INDEX(J19:J21,$D$6) -> 0.0043 | K17: =INDEX(K19:K21,$D$6) -> 0.0043 | L17: =INDEX(L19:L21,$D$6) -> 0.0044 | M17: =INDEX(M19:M21,$D$6) -> 0.0045 | N17: =INDEX(N19:N21,$D$6) -> 0.0045
B19: Best Case | I19: 0.0042 | J19: 0.0044 | K19: 0.0046 | L19: 0.0048 | M19: 0.005 | N19: =M19 -> 0.005 | P19: Other revenue (royalty and licensing-type income) as % of sales. FY23–25 range 0.38–0.44%; the Best Case trends gently upward with stronger sales momentum. | Term (N), all scenarios: held at the 2030 ratio so that margins are stable in perpetuity.
B20: Base Case | I20: 0.0042 | J20: 0.0043 | K20: 0.0043 | L20: 0.0044 | M20: 0.0045 | N20: =M20 -> 0.0045 | P20: Held at 0.42–0.45% of sales, close to the FY2025 level (0.44%) and slightly above the FY23–25 average (0.41%).
B21: Worst Case | I21: 0.0038 | J21: 0.0035 | K21: 0.003 | L21: 0.0033 | M21: 0.0036 | N21: =M21 -> 0.0036 | P21: Compressed during the 2028–29 downturn on lower royalty and licensing volumes, recovering partially by 2030.
B24: COGS | I24: =INDEX(I26:I28,$D$6) -> 0.00090441985 | J24: =INDEX(J26:J28,$D$6) -> 0.018740719 | K24: =INDEX(K26:K28,$D$6) -> 0.017768006 | L24: =INDEX(L26:L28,$D$6) -> 0.018371853 | M24: =INDEX(M26:M28,$D$6) -> 0.025530179 | N24: =INDEX(N26:N28,$D$6) -> 0.015
B26: Best Case | I26: 0.015082154 | J26: 0.028739312 | K26: 0.030626201 | L26: 0.034982241 | M26: 0.035676958 | N26: =N12 -> 0.02 | P26: COGS is projected as a growth rate on the prior year and is the main lever for the gross-margin path. In the Best Case COGS grows slower than sales, supported by 'Fuel for Growth' procurement savings (CHF 3bn gross savings target by end-2027) and easing cocoa and coffee costs. | Term (N), all scenarios: COGS grows at the terminal sales growth rate, freezing the 2030 gross margin in perpetuity (no margin drift in the terminal year).
B27: Base Case | I27: 0.00090441985 | J27: 0.018740719 | K27: 0.017768006 | L27: 0.018371853 | M27: 0.025530179 | N27: =N13 -> 0.015 | P27: Calibrated so that the EBITDA margin moves from 17.5% (2026) to 18.3% (2030), recovering above the FY2025 level (17.7%) but staying below FY2024 (20.0%), as coffee and cocoa cost relief and 'Fuel for Growth' savings are partly reinvested.
B28: Worst Case | I28: -0.010364991 | J28: 0.00033932446 | K28: -0.052572217 | L28: -0.0018388641 | M28: -5.4555294e-05 | N28: =N14 -> 0.01 | P28: In the 2028 shock year COGS falls less than sales (–5.3% vs –5.5%): input costs and FX stay elevated while volumes soften, the typical operating-deleverage pattern for consumer staples in a downturn.
B31: Distribution expenses | I31: =INDEX(I33:I35,$D$6) -> 0.081 | J31: =INDEX(J33:J35,$D$6) -> 0.0805 | K31: =INDEX(K33:K35,$D$6) -> 0.08 | L31: =INDEX(L33:L35,$D$6) -> 0.0795 | M31: =INDEX(M33:M35,$D$6) -> 0.079 | N31: =INDEX(N33:N35,$D$6) -> 0.079
B33: Best Case | I33: 0.08 | J33: 0.0785 | K33: 0.077 | L33: 0.0755 | M33: 0.074 | N33: =M33 -> 0.074 | P33: Distribution costs as % of sales continue the FY23–25 decline (8.3% to 8.2%) through logistics and network efficiencies, reaching 7.4% by 2030. | Term (N), all scenarios: held at the 2030 ratio (steady state).
B34: Base Case | I34: 0.081 | J34: 0.0805 | K34: 0.08 | L34: 0.0795 | M34: 0.079 | N34: =M34 -> 0.079 | P34: Gradual improvement from the FY2025 level (8.2%) to 7.9% by 2030 from ongoing logistics and network efficiency.
B35: Worst Case | I35: 0.083 | J35: 0.085 | K35: 0.09 | L35: 0.087 | M35: 0.084 | N35: =M35 -> 0.084 | P35: Rises to 9.0% in 2028 as freight costs increase and lower volumes absorb fixed distribution costs, then partially normalises.
B38: Marketing & administration expenses | I38: =INDEX(I40:I42,$D$6) -> 0.2 | J38: =INDEX(J40:J42,$D$6) -> 0.201 | K38: =INDEX(K40:K42,$D$6) -> 0.201 | L38: =INDEX(L40:L42,$D$6) -> 0.202 | M38: =INDEX(M40:M42,$D$6) -> 0.203 | N38: =INDEX(N40:N42,$D$6) -> 0.203
B40: Best Case | I40: 0.201 | J40: 0.203 | K40: 0.205 | L40: 0.206 | M40: 0.208 | N40: =M40 -> 0.208 | P40: Includes a deliberate step-up in advertising and promotion, in line with management's stated intent to lift A&P toward c.9% of sales, within a Marketing & Administration total that has run at 19–20% of sales; reaches 20.8% by 2030. | Term (N), all scenarios: held at the 2030 ratio (steady state).
B41: Base Case | I41: 0.2 | J41: 0.201 | K41: 0.201 | L41: 0.202 | M41: 0.203 | N41: =M41 -> 0.203 | P41: Modest reinvestment from 20.0% to 20.3% of sales, broadly in line with the FY2025 level (20.0%).
B42: Worst Case | I42: 0.197 | J42: 0.202 | K42: 0.213 | L42: 0.205 | M42: 0.199 | N42: =M42 -> 0.199 | P42: Rises to 21.3% in 2028: overheads are less flexible than marketing spend, so the ratio increases even as A&P is reduced; it partially normalises thereafter.
B45: Other trading income | I45: =INDEX(I47:I49,$D$6) -> 0.0014 | J45: =INDEX(J47:J49,$D$6) -> 0.0014 | K45: =INDEX(K47:K49,$D$6) -> 0.0013 | L45: =INDEX(L47:L49,$D$6) -> 0.0014 | M45: =INDEX(M47:M49,$D$6) -> 0.0014 | N45: =INDEX(N47:N49,$D$6) -> 0.0014
B47: Best Case | I47: 0.0016 | J47: 0.0017 | K47: 0.0017 | L47: 0.0018 | M47: 0.0018 | N47: =M47 -> 0.0018 | P47: Small and historically volatile line (FY23–25: 0.14–0.15% of sales); the Best Case is slightly higher. | Term (N), all scenarios: held at the 2030 ratio (steady state).
B48: Base Case | I48: 0.0014 | J48: 0.0014 | K48: 0.0013 | L48: 0.0014 | M48: 0.0014 | N48: =M48 -> 0.0014 | P48: Held near the FY23–25 average.
B49: Worst Case | I49: 0.0008 | J49: 0.0006 | K49: 0.0005 | L49: 0.0007 | M49: 0.0009 | N49: =M49 -> 0.0009 | P49: Compressed during the 2028–29 downturn.
B52: Other trading expenses | I52: =INDEX(I54:I56,$D$6) -> 0.024 | J52: =INDEX(J54:J56,$D$6) -> 0.019 | K52: =INDEX(K54:K56,$D$6) -> 0.015 | L52: =INDEX(L54:L56,$D$6) -> 0.0115 | M52: =INDEX(M54:M56,$D$6) -> 0.0095 | N52: =INDEX(N54:N56,$D$6) -> 0.0095
B54: Best Case | I54: 0.022 | J54: 0.017 | K54: 0.013 | L54: 0.01 | M54: 0.0085 | N54: =M54 -> 0.0085 | P54: Elevated in 2026–27 by 'Fuel for Growth' restructuring and impairment-type charges (c.16,000 role reductions by end-2027, announced in Q4 2025), fading from 2028 as the programme completes; the Best Case assumes faster execution. | Term (N): Best and Base held at the 2030 ratio, by which point the restructuring programme is complete.
B55: Base Case | I55: 0.024 | J55: 0.019 | K55: 0.015 | L55: 0.0115 | M55: 0.0095 | N55: =M55 -> 0.0095 | P55: H1 2026 other trading expenses ran at 1.9% of sales (restructuring and net other trading items CHF 0.8bn vs CHF 0.4bn in H1 2025) as 'Fuel for Growth' restructuring accelerated; 2.4% for the full year allows for H2 phasing, declining to 0.95% of sales by 2030 as the programme completes.
B56: Worst Case | I56: 0.027 | J56: 0.025 | K56: 0.034 | L56: 0.021 | M56: 0.016 | N56: 0.012 | P56: Adds further impairment and restructuring charges in the 2028 shock year (3.4% of sales) on top of the ongoing programme, before receding. | Term (N): normalised to 1.2% – the 2030 ratio (1.6%) still carries downturn-related charges, and one-off costs should not be capitalised into perpetuity.
B59: Other operating income | I59: =INDEX(I61:I63,$D$6) -> 0.003 | J59: =INDEX(J61:J63,$D$6) -> 0.0028 | K59: =INDEX(K61:K63,$D$6) -> 0.0027 | L59: =INDEX(L61:L63,$D$6) -> 0.0028 | M59: =INDEX(M61:M63,$D$6) -> 0.0028 | N59: =INDEX(N61:N63,$D$6) -> 0.0028
B61: Best Case | I61: 0.0035 | J61: 0.0035 | K61: 0.0035 | L61: 0.0034 | M61: 0.0034 | N61: =M61 -> 0.0034 | P61: Historically volatile, disposal-gain-type line (FY23–25: 0.28–0.52% of sales); the Best Case assumes slightly more portfolio gains. | Term (N), all scenarios: held at the 2030 ratio (steady state).
B62: Base Case | I62: 0.003 | J62: 0.0028 | K62: 0.0027 | L62: 0.0028 | M62: 0.0028 | N62: =M62 -> 0.0028 | P62: Held near the FY2025 level (0.28% of sales), below the FY23–25 average (0.37%), which included higher disposal gains in 2024.
B63: Worst Case | I63: 0.0015 | J63: 0.0012 | K63: 0.001 | L63: 0.0012 | M63: 0.0015 | N63: =M63 -> 0.0015 | P63: Compressed in the downturn as fewer disposal gains are realised.
B66: Other operating expenses | I66: =INDEX(I68:I70,$D$6) -> 0.006 | J66: =INDEX(J68:J70,$D$6) -> 0.0055 | K66: =INDEX(K68:K70,$D$6) -> 0.0052 | L66: =INDEX(L68:L70,$D$6) -> 0.005 | M66: =INDEX(M68:M70,$D$6) -> 0.0048 | N66: =INDEX(N68:N70,$D$6) -> 0.0048
B68: Best Case | I68: 0.005 | J68: 0.0045 | K68: 0.0042 | L68: 0.004 | M68: 0.0038 | N68: =M68 -> 0.0038 | P68: Historically 0.42–0.81% of sales (FY23–25); the Best Case trends lower. | Term (N): Best and Base held at the 2030 ratio.
B69: Base Case | I69: 0.006 | J69: 0.0055 | K69: 0.0052 | L69: 0.005 | M69: 0.0048 | N69: =M69 -> 0.0048 | P69: 0.60% of sales in 2026 easing to 0.48% by 2030, below FY2025 (0.73%, incl. infant-formula inventory write-offs). Excludes the CHF 1.3bn one-off non-cash write-down on assets held for sale booked in H1 2026, so reported 2026 net profit will be lower than modelled; the non-cash share of this line is added back in the cash flow via row 168.
B70: Worst Case | I70: 0.0085 | J70: 0.01 | K70: 0.0135 | L70: 0.0105 | M70: 0.0085 | N70: 0.007 | P70: Rises to 1.35% of sales in the 2028 trough, then recedes. | Term (N): normalised to 0.7% (vs 0.85% in 2030) for the same reason as other trading expenses – downturn charges are not carried into perpetuity.
...

Sheet Model
B2: ="Nestlé S.A. | CHF millions | Scenario: "&INDEX(Input!$B$12:$B$14,Input!$D$6) -> Nestlé S.A. | CHF millions | Scenario: Base Case | F2: =G2-1 -> 2023 | G2: =H2-1 -> 2024 | H2: =I2-1 -> 2025 | I2: =Input!$I$2 -> 2026 | J2: =I2+1 -> 2027 | K2: =J2+1 -> 2028 | L2: =K2+1 -> 2029 | M2: =L2+1 -> 2030 | N2: Term
B4: Growth & Margin Drivers
B6: =Input!$B$8 -> All figures in CHF millions unless stated | F6: =F$2 -> 2023 | G6: =G$2 -> 2024 | H6: =H$2 -> 2025 | I6: =I$2 -> 2026 | J6: =J$2 -> 2027 | K6: =K$2 -> 2028 | L6: =L$2 -> 2029 | M6: =M$2 -> 2030 | N6: =N$2 -> Term
B7: =CONCATENATE("Model Running: ",INDEX(Input!$B$12:$B$14,Input!$D$6)," Drivers") -> Model Running: Base Case Drivers
B9: Sales growth | G9: -0.0176778 | H9: -0.020404142 | I9: =Input!I$10 -> 0.005 | J9: =Input!J$10 -> 0.015 | K9: =Input!K$10 -> 0.005 | L9: =Input!L$10 -> 0.02 | M9: =Input!M$10 -> 0.028 | N9: =Input!N$10 -> 0.015
B10: Other revenue | F10: 0.0037957806 | G10: 0.0040063927 | H10: 0.004413901 | I10: =Input!I$17 -> 0.0042 | J10: =Input!J$17 -> 0.0043 | K10: =Input!K$17 -> 0.0043 | L10: =Input!L$17 -> 0.0044 | M10: =Input!M$17 -> 0.0045 | N10: =Input!N$17 -> 0.0045
B11: Cost of goods sold | G11: -0.032943888 | H11: 0.00049311691 | I11: =Input!I$24 -> 0.00090441985 | J11: =Input!J$24 -> 0.018740719 | K11: =Input!K$24 -> 0.017768006 | L11: =Input!L$24 -> 0.018371853 | M11: =Input!M$24 -> 0.025530179 | N11: =Input!N$24 -> 0.015
B12: Distribution expenses | F12: 0.083496419 | G12: 0.082831622 | H12: 0.081640407 | I12: =Input!I$31 -> 0.081 | J12: =Input!J$31 -> 0.0805 | K12: =Input!K$31 -> 0.08 | L12: =Input!L$31 -> 0.0795 | M12: =Input!M$31 -> 0.079 | N12: =Input!N$31 -> 0.079
B13: Marketing & administration expenses | F13: 0.18870298 | G13: 0.19826171 | H13: 0.19983238 | I13: =Input!I$38 -> 0.2 | J13: =Input!J$38 -> 0.201 | K13: =Input!K$38 -> 0.201 | L13: =Input!L$38 -> 0.202 | M13: =Input!M$38 -> 0.203 | N13: =Input!N$38 -> 0.203
B14: R&D costs | F14: 0.017806835 | G14: 0.018247696 | H14: 0.01802436 | I14: =Input!$F$183 -> 0.018 | J14: =Input!$F$183 -> 0.018 | K14: =Input!$F$183 -> 0.018 | L14: =Input!$F$183 -> 0.018 | M14: =Input!$F$183 -> 0.018 | N14: =Input!$F$183 -> 0.018
B15: Other trading income | F15: 0.0014193854 | G15: 0.0013573571 | H15: 0.0015085484 | I15: =Input!I$45 -> 0.0014 | J15: =Input!J$45 -> 0.0014 | K15: =Input!K$45 -> 0.0013 | L15: =Input!L$45 -> 0.0014 | M15: =Input!M$45 -> 0.0014 | N15: =Input!N$45 -> 0.0014
B16: Other trading expenses | F16: 0.017903611 | G16: 0.013080982 | H16: 0.020661526 | I16: =Input!I$52 -> 0.024 | J16: =Input!J$52 -> 0.019 | K16: =Input!K$52 -> 0.015 | L16: =Input!L$52 -> 0.0115 | M16: =Input!M$52 -> 0.0095 | N16: =Input!N$52 -> 0.0095
B17: Other operating income | F17: 0.00320437 | G17: 0.005188607 | H17: 0.0028271315 | I17: =Input!I$59 -> 0.003 | J17: =Input!J$59 -> 0.0028 | K17: =Input!K$59 -> 0.0027 | L17: =Input!L$59 -> 0.0028 | M17: =Input!M$59 -> 0.0028 | N17: =Input!N$59 -> 0.0028
B18: Other operating expenses | F18: 0.0081184542 | G18: 0.004192482 | H18: 0.0072745558 | I18: =Input!I$66 -> 0.006 | J18: =Input!J$66 -> 0.0055 | K18: =Input!K$66 -> 0.0052 | L18: =Input!L$66 -> 0.005 | M18: =Input!M$66 -> 0.0048 | N18: =Input!N$66 -> 0.0048
B19: Effective tax rate | F19: 0.18216169 | G19: 0.25032102 | H19: 0.24555855 | I19: =Input!$M$173 -> 0.235 | J19: =Input!$M$173 -> 0.235 | K19: =Input!$M$173 -> 0.235 | L19: =Input!$M$173 -> 0.235 | M19: =Input!$M$173 -> 0.235 | N19: =Input!$M$173 -> 0.235
B20: Income from associates & JV | G20: 0.11517857 | H20: -0.084867894 | I20: =Input!I$73 -> 0.03 | J20: =Input!J$73 -> 0.04 | K20: =Input!K$73 -> 0.04 | L20: =Input!L$73 -> 0.05 | M20: =Input!M$73 -> 0.05 | N20: =Input!N$73 -> 0.015
B21: Non-controlling interests | F21: 0.026066557 | G21: 0.025953105 | H21: 0.023881565 | I21: =Input!$F$182 -> 0.025 | J21: =Input!$F$182 -> 0.025 | K21: =Input!$F$182 -> 0.025 | L21: =Input!$F$182 -> 0.025 | M21: =Input!$F$182 -> 0.025 | N21: =Input!$F$182 -> 0.025
B22: Non-cash share of other trading & operating expenses | F22: =IFERROR(F474/-(F447+F451),0) -> 0.26735537 | G22: =IFERROR(G474/-(G447+G451),0) -> 0.36755387 | H22: =IFERROR(H474/-(H447+H451),0) -> 0.3692 | I22: =Input!I$168 -> 0.35 | J22: =Input!J$168 -> 0.35 | K22: =Input!K$168 -> 0.35 | L22: =Input!L$168 -> 0.35 | M22: =Input!M$168 -> 0.35 | N22: =Input!N$168 -> 0
B24: Equity & Dividend Drivers
B26: =Input!$B$8 -> All figures in CHF millions unless stated | F26: =F$2 -> 2023 | G26: =G$2 -> 2024 | H26: =H$2 -> 2025 | I26: =I$2 -> 2026 | J26: =J$2 -> 2027 | K26: =K$2 -> 2028 | L26: =L$2 -> 2029 | M26: =M$2 -> 2030 | N26: =N$2 -> Term
B27: =CONCATENATE("Model Running: ",INDEX(Input!$B$12:$B$14,Input!$D$6)," Drivers") -> Model Running: Base Case Drivers
B29: Dividend payout ratio, % of net profit (parent) | F29: 0.6984566 | G29: 0.71811834 | H29: 0.86892505 | I29: =Input!I$134 -> 0.865 | J29: =Input!J$134 -> 0.842 | K29: =Input!K$134 -> 0.859 | L29: =Input!L$134 -> 0.823 | M29: =Input!M$134 -> 0.79 | N29: =Input!N$134 -> 0.79
B30: Dividends to NCI, % of NCI profit | F30: 1.0766667 | G30: 0.6 | H30: 0.77828054 | I30: =Input!I$155 -> 0.75 | J30: =Input!J$155 -> 0.75 | K30: =Input!K$155 -> 0.75 | L30: =Input!L$155 -> 0.75 | M30: =Input!M$155 -> 0.75 | N30: =Input!N$155 -> 0.75
B31: Treasury share purchases, CHF mm/year | F31: 5234 | G31: 4678 | H31: 213 | I31: =IF((H549+H560+H556-H526)/(H452+H473)>Input!$F$185,0,Input!I$141) -> 0 | J31: =IF((I549+I560+I556-I526)/(I452+I473)>Input!$F$185,0,Input!J$141) -> 0 | K31: =IF((J549+J560+J556-J526)/(J452+J473)>Input!$F$185,0,Input!K$141) -> 0 | L31: =IF((K549+K560+K556-K526)/(K452+K473)>Input!$F$185,0,Input!L$141) -> 0 | M31: =IF((L549+L560+L556-L526)/(L452+L473)>Input!$F$185,0,Input!M$141) -> 2000 | N31: =Input!N$141 -> 2000
B32: Dividends received from associates & JV, % of opening balance | G32: 0.057992054 | H32: 0.19223789 | I32: =Input!I$148 -> 0.065 | J32: =Input!J$148 -> 0.06 | K32: =Input!K$148 -> 0.06 | L32: =Input!L$148 -> 0.06 | M32: =Input!M$148 -> 0.06 | N32: =Input!N$148 -> 0.06
B35: Working Capital Schedule
B37: =Input!$B$8 -> All figures in CHF millions unless stated | F37: =F$2 -> 2023 | G37: =G$2 -> 2024 | H37: =H$2 -> 2025 | I37: =I$2 -> 2026 | J37: =J$2 -> 2027 | K37: =K$2 -> 2028 | L37: =L$2 -> 2029 | M37: =M$2 -> 2030 | N37: =N$2 -> Term
B38: =CONCATENATE("Model Running: ",INDEX(Input!$B$12:$B$14,Input!$D$6)," Drivers") -> Model Running: Base Case Drivers
B40: Days in Period | F40: =Input!$F$174 -> 365 | G40: =Input!$F$174 -> 365 | H40: =Input!$F$174 -> 365 | I40: =Input!$F$174 -> 365 | J40: =Input!$F$174 -> 365 | K40: =Input!$F$174 -> 365 | L40: =Input!$F$174 -> 365 | M40: =Input!$F$174 -> 365 | N40: =Input!$F$174 -> 365
B41: Revenue | F41: =F440 -> 92998 | G41: =G440 -> 91354 | H41: =H440 -> 89490 | I41: =I440 -> 89937.45 | J41: =J440 -> 91286.512 | K41: =K440 -> 91742.944 | L41: =L440 -> 93577.803 | M41: =M440 -> 96197.982 | N41: =N440 -> 97640.951
B42: COGS | F42: =-F442 -> 50328 | G42: =-G442 -> 48670 | H42: =-H442 -> 48694 | I42: =-I442 -> 48738.04 | J42: =-J442 -> 49651.426 | K42: =-K442 -> 50533.633 | L42: =-L442 -> 51462.029 | M42: =-M442 -> 52775.864 | N42: =-N442 -> 53567.502
B44: AMOUNTS PER DAY
B45: Accounts Receivable (Days) | F45: =(F52/F41)*F40 -> 43.153347 | G45: =(G52/G41)*G40 -> 44.952766 | H45: =(H52/H41)*H40 -> 43.074813 | I45: =Input!I86 -> 43 | J45: =Input!J86 -> 43 | K45: =Input!K86 -> 42.5 | L45: =Input!L86 -> 42 | M45: =Input!M86 -> 42 | N45: =Input!N86 -> 42
B46: Inventory (Days) | F46: =(F53/F42)*F40 -> 86.274837 | G46: =(G53/G42)*G40 -> 99.443189 | H46: =(H53/H42)*H40 -> 96.043558 | I46: =Input!I93 -> 93 | J46: =Input!J93 -> 91 | K46: =Input!K93 -> 89 | L46: =Input!L93 -> 88 | M46: =Input!M93 -> 87 | N46: =Input!N93 -> 87
B47: Accounts Payable (Days) | F47: =(F54/F42)*F40 -> 139.27555 | G47: =(G54/G42)*G40 -> 163.5413 | H47: =(H54/H42)*H40 -> 150.0882 | I47: =Input!I100 -> 150 | J47: =Input!J100 -> 150 | K47: =Input!K100 -> 150 | L47: =Input!L100 -> 150 | M47: =Input!M100 -> 150 | N47: =Input!N100 -> 150
B48: Prepayments (Days) | F48: =(F55/F41)*F40 -> 2.0448289 | G48: =(G55/G41)*G40 -> 2.1695273 | H48: =(H55/H41)*H40 -> 1.953682 | I48: =Input!I107 -> 2 | J48: =Input!J107 -> 2 | K48: =Input!K107 -> 2 | L48: =Input!L107 -> 2 | M48: =Input!M107 -> 2 | N48: =Input!N107 -> 2
B49: Accruals (Days) | F49: =(F56/F42)*F40 -> 37.074392 | G49: =(G56/G42)*G40 -> 40.992192 | H49: =(H56/H42)*H40 -> 41.789029 | I49: =Input!I108 -> 40 | J49: =Input!J108 -> 40 | K49: =Input!K108 -> 40 | L49: =Input!L108 -> 41 | M49: =Input!M108 -> 41 | N49: =Input!N108 -> 41
B51: TOTAL AMOUNTS
B52: Accounts Receivable | F52: 10995 | G52: 11251 | H52: 10561 | I52: =(I45/I40)*I41 -> 10595.371 | J52: =(J45/J40)*J41 -> 10754.301 | K52: =(K45/K40)*K41 -> 10682.398 | L52: =(L45/L40)*L41 -> 10767.857 | M52: =(M45/M40)*M41 -> 11069.357 | N52: =(N45/N40)*N41 -> 11235.397
B53: Inventory | F53: 11896 | G53: 13260 | H53: 12813 | I53: =(I46/I40)*I42 -> 12418.185 | J53: =(J46/J40)*J42 -> 12378.849 | K53: =(K46/K40)*K42 -> 12321.899 | L53: =(L46/L40)*L42 -> 12407.284 | M53: =(M46/M40)*M42 -> 12579.452 | N53: =(N46/N40)*N42 -> 12768.144
...
