Workbook
Name ScenarioSwitch: Input!$D$6

Sheet Cover
C4: 3-Statement Modeling | L4: CONFIDENTIAL
C7: Table of Contents | J7: Model Checks
C9: Dashboard | J9: Unused Tax Losses Remaining? | L9: =Model!$D$128 -> 0
C10: Ouput | J10: Balance Sheet Unbalanced? | L10: =IF(ROUND(SUMPRODUCT(ABS(Model!$F$395:$M$395)),2)=0,0,1) -> 0
C11: Input
C12: Model
C14: Model Guide
C16: Adjustable Input | D16: (Grey Cell)
C17: Hardcode | D17: (Blue Font)
C18: Formula | D18: (Black Font)
P19: Do Not
C20: Model Circularity | P20: Delete
C22: Circularity Switch | D22: 0 | P22: Circularity
P23: 1
C24: =IF($D$22=1,"This model now has the circularity turned on. Please confirm the Excel settings below","") | P24: 0
C25: =IF($D$22=1,"PC","") | D25: =IF($D$22=1,"File - Options - Formulas - Check the box on the top-right labeled 'Enable iterative calculation'.","")
C26: =IF($D$22=1,"Mac","") | D26: =IF($D$22=1,"Excel - Preferences - Calculation - Check the box near the bottom labeled 'Use iterative calculation'.","")
C28: DISCLAIMER & NOTICE OF INTENT
C29: 1. Independent Portfolio Project: This financial model and dashboard were prepared solely by the author, in a personal capacity, to demonstrate
C30: skills in financial modeling and financial statement analysis. They do not reflect the views of any employer.
C31: 2. Public Data Sources: Historical figures are drawn from publicly available sources (Nestlé Investor Relations / Annual Reports). Forecasts and
C32: scenarios (Best / Base / Worst) are the author's own illustrative assumptions, not forecasts issued by Nestlé.
C33: 3. No Affiliation: This project is not affiliated with, authorized by, or endorsed by Nestlé S.A. Nestlé and related names and marks are the
C34: property of their respective owners and are used for identification only.
C35: 4. No Advice: Nothing herein constitutes investment advice, equity research, or a recommendation to buy or sell any security.

Sheet Dashboard
Q1: EXECUTIVE FINANCIAL DASHBOARD
B2: ="Nestlé S.A. | CHF millions | Model Scenario: " -> Nestlé S.A. | CHF millions | Model Scenario: | F2: 2 | O2: Reporting year ▸ | P2: 2026F
B4: Key Performance Indicators
B6: REVENUE (CHF m) | D6: EBITDA MARGIN | F6: NET PROFIT (CHF m) | H6: FREE CASH FLOW (CHF m) | J6: ROE | L6: ROIC | N6: NET DEBT / EBITDA | P6: CASH CONVERSION CYCLE
B7: =$P$101 -> 90315.187 | D7: =$P$104 -> 0.17526389 | F7: =$P$107 -> 9486.3323 | H7: =$P$126 -> 8966.7167 | J7: =$P$108 -> 0.27603888 | L7: =$P$110 -> 0.10907626 | N7: =$P$127 -> 3.3157317 | P7: =$P$114 -> -14.179845
B8: =IF(ISNUMBER($Q$101),IF($P$101>=$Q$101,"▲ ","▼ ")&TEXT(ABS($P$101/$Q$101-1),"0.0%")&" vs "&$Q$99,"n.a.") -> ▲ 0.5% vs 2025A | D8: =IF(ISNUMBER($Q$104),IF($P$104>=$Q$104,"▲ ","▼ ")&TEXT(ABS($P$104-$Q$104)*100,"0.0")&" pp vs "&$Q$99,"n.a.") -> ▼ 0.2 pp vs 2025A | F8: =IF(ISNUMBER($Q$107),IF($P$107>=$Q$107,"▲ ","▼ ")&TEXT(ABS($P$107/$Q$107-1),"0.0%")&" vs "&$Q$99,"n.a.") -> ▲ 2.5% vs 2025A | H8: =IF(ISNUMBER($Q$126),IF($P$126>=$Q$126,"▲ ","▼ ")&TEXT(ABS($P$126/$Q$126-1),"0.0%")&" vs "&$Q$99,"n.a.") -> ▼ 18.4% vs 2025A | J8: =IF(ISNUMBER($Q$108),IF($P$108>=$Q$108,"▲ ","▼ ")&TEXT(ABS($P$108-$Q$108)*100,"0.0")&" pp vs "&$Q$99,"n.a.") -> ▼ 0.4 pp vs 2025A | L8: =IF(ISNUMBER($Q$110),IF($P$110>=$Q$110,"▲ ","▼ ")&TEXT(ABS($P$110-$Q$110)*100,"0.0")&" pp vs "&$Q$99,"n.a.") -> ▲ 0.2 pp vs 2025A | N8: =IF(ISNUMBER($Q$127),IF($P$127>=$Q$127,"▲ ","▼ ")&TEXT(ABS($P$127-$Q$127),"0.00")&"x vs "&$Q$99,"n.a.") -> ▼ 0.03x vs 2025A | P8: =IF(ISNUMBER($Q$114),IF($P$114>=$Q$114,"▲ ","▼ ")&TEXT(ABS($P$114-$Q$114),"0.0")&" days vs "&$Q$99,"n.a.") -> ▼ 3.0 days vs 2025A
B10: Income Summary | J10: Cash Flow
B30: Revenue & Profitability Margin | J30: Net Profit vs Free Cash Flow
B50: Expenses Summary | J50: Working Capital Cycle
B70: Cash Generation Sensitivity | J70: Liquidity Sensitivity
B72: Sensitivity inputs | J72: Sensitivity inputs
B73: Revenue Growth Step | D73: 0.01 | J73: DSO | L73: 2
B74: EBITDA Margin Step | D74: 0.02 | J74: DPO | L74: 5
D77: Free Cash Flow | L77: Cash Balance
D79: Revenue Growth | L79: DSO
C80: =$P$126 -> 8966.7167 | D80: =E80-$D$73 -> -0.015214026 | E80: =F80-$D$73 -> -0.0052140258 | F80: =$P$100 -> 0.0047859742 | G80: =F80+$D$73 -> 0.014785974 | H80: =G80+$D$73 -> 0.024785974 | K80: =$P$124 -> 4210.2724 | L80: =M80+$L$73 -> 46.820155 | M80: =N80+$L$73 -> 44.820155 | N80: =$P$111 -> 42.820155 | O80: =N80-$L$73 -> 40.820155 | P80: =O80-$L$73 -> 38.820155
B81: EBITDA Margin | C81: =C82+$D$74 -> 0.21526389 | D81: =$C$80+(($Q$101*(1+D$80)*$C81)-$P$102)*(1-$P$137) -> 11434.322 | E81: =$C$80+(($Q$101*(1+E$80)*$C81)-$P$102)*(1-$P$137) -> 11582.342 | F81: =$C$80+(($Q$101*(1+F$80)*$C81)-$P$102)*(1-$P$137) -> 11730.361 | G81: =$C$80+(($Q$101*(1+G$80)*$C81)-$P$102)*(1-$P$137) -> 11878.381 | H81: =$C$80+(($Q$101*(1+H$80)*$C81)-$P$102)*(1-$P$137) -> 12026.401 | J81: DPO | K81: =K82+$L$74 -> 160 | L81: =$K$80-(L$80-$N$80)*$P$101/365-($K81-$K$83)*$P$142/365 -> 4555.8057 | M81: =$K$80-(M$80-$N$80)*$P$101/365-($K81-$K$83)*$P$142/365 -> 5050.6834 | N81: =$K$80-(N$80-$N$80)*$P$101/365-($K81-$K$83)*$P$142/365 -> 5545.5612 | O81: =$K$80-(O$80-$N$80)*$P$101/365-($K81-$K$83)*$P$142/365 -> 6040.4389 | P81: =$K$80-(P$80-$N$80)*$P$101/365-($K81-$K$83)*$P$142/365 -> 6535.3167
C82: =C83+$D$74 -> 0.19526389 | D82: =$C$80+(($Q$101*(1+D$80)*$C82)-$P$102)*(1-$P$137) -> 10080.004 | E82: =$C$80+(($Q$101*(1+E$80)*$C82)-$P$102)*(1-$P$137) -> 10214.272 | F82: =$C$80+(($Q$101*(1+F$80)*$C82)-$P$102)*(1-$P$137) -> 10348.539 | G82: =$C$80+(($Q$101*(1+G$80)*$C82)-$P$102)*(1-$P$137) -> 10482.806 | H82: =$C$80+(($Q$101*(1+H$80)*$C82)-$P$102)*(1-$P$137) -> 10617.074 | K82: =K83+$L$74 -> 155 | L82: =$K$80-(L$80-$N$80)*$P$101/365-($K82-$K$83)*$P$142/365 -> 3888.1613 | M82: =$K$80-(M$80-$N$80)*$P$101/365-($K82-$K$83)*$P$142/365 -> 4383.0391 | N82: =$K$80-(N$80-$N$80)*$P$101/365-($K82-$K$83)*$P$142/365 -> 4877.9168 | O82: =$K$80-(O$80-$N$80)*$P$101/365-($K82-$K$83)*$P$142/365 -> 5372.7945 | P82: =$K$80-(P$80-$N$80)*$P$101/365-($K82-$K$83)*$P$142/365 -> 5867.6723
C83: =$P$104 -> 0.17526389 | D83: =$C$80+(($Q$101*(1+D$80)*$C83)-$P$102)*(1-$P$137) -> 8725.6866 | E83: =$C$80+(($Q$101*(1+E$80)*$C83)-$P$102)*(1-$P$137) -> 8846.2016 | F83: =$C$80+(($Q$101*(1+F$80)*$C83)-$P$102)*(1-$P$137) -> 8966.7167 | G83: =$C$80+(($Q$101*(1+G$80)*$C83)-$P$102)*(1-$P$137) -> 9087.2317 | H83: =$C$80+(($Q$101*(1+H$80)*$C83)-$P$102)*(1-$P$137) -> 9207.7467 | K83: =$P$113 -> 150 | L83: =$K$80-(L$80-$N$80)*$P$101/365-($K83-$K$83)*$P$142/365 -> 3220.5169 | M83: =$K$80-(M$80-$N$80)*$P$101/365-($K83-$K$83)*$P$142/365 -> 3715.3947 | N83: =$K$80-(N$80-$N$80)*$P$101/365-($K83-$K$83)*$P$142/365 -> 4210.2724 | O83: =$K$80-(O$80-$N$80)*$P$101/365-($K83-$K$83)*$P$142/365 -> 4705.1502 | P83: =$K$80-(P$80-$N$80)*$P$101/365-($K83-$K$83)*$P$142/365 -> 5200.0279
C84: =C83-$D$74 -> 0.15526389 | D84: =$C$80+(($Q$101*(1+D$80)*$C84)-$P$102)*(1-$P$137) -> 7371.3691 | E84: =$C$80+(($Q$101*(1+E$80)*$C84)-$P$102)*(1-$P$137) -> 7478.1317 | F84: =$C$80+(($Q$101*(1+F$80)*$C84)-$P$102)*(1-$P$137) -> 7584.8943 | G84: =$C$80+(($Q$101*(1+G$80)*$C84)-$P$102)*(1-$P$137) -> 7691.6569 | H84: =$C$80+(($Q$101*(1+H$80)*$C84)-$P$102)*(1-$P$137) -> 7798.4195 | K84: =K83-$L$74 -> 145 | L84: =$K$80-(L$80-$N$80)*$P$101/365-($K84-$K$83)*$P$142/365 -> 2552.8726 | M84: =$K$80-(M$80-$N$80)*$P$101/365-($K84-$K$83)*$P$142/365 -> 3047.7503 | N84: =$K$80-(N$80-$N$80)*$P$101/365-($K84-$K$83)*$P$142/365 -> 3542.628 | O84: =$K$80-(O$80-$N$80)*$P$101/365-($K84-$K$83)*$P$142/365 -> 4037.5058 | P84: =$K$80-(P$80-$N$80)*$P$101/365-($K84-$K$83)*$P$142/365 -> 4532.3835
C85: =C84-$D$74 -> 0.13526389 | D85: =$C$80+(($Q$101*(1+D$80)*$C85)-$P$102)*(1-$P$137) -> 6017.0515 | E85: =$C$80+(($Q$101*(1+E$80)*$C85)-$P$102)*(1-$P$137) -> 6110.0617 | F85: =$C$80+(($Q$101*(1+F$80)*$C85)-$P$102)*(1-$P$137) -> 6203.0719 | G85: =$C$80+(($Q$101*(1+G$80)*$C85)-$P$102)*(1-$P$137) -> 6296.0821 | H85: =$C$80+(($Q$101*(1+H$80)*$C85)-$P$102)*(1-$P$137) -> 6389.0923 | K85: =K84-$L$74 -> 140 | L85: =$K$80-(L$80-$N$80)*$P$101/365-($K85-$K$83)*$P$142/365 -> 1885.2282 | M85: =$K$80-(M$80-$N$80)*$P$101/365-($K85-$K$83)*$P$142/365 -> 2380.1059 | N85: =$K$80-(N$80-$N$80)*$P$101/365-($K85-$K$83)*$P$142/365 -> 2874.9837 | O85: =$K$80-(O$80-$N$80)*$P$101/365-($K85-$K$83)*$P$142/365 -> 3369.8614 | P85: =$K$80-(P$80-$N$80)*$P$101/365-($K85-$K$83)*$P$142/365 -> 3864.7391
C86: =C85-$D$74 -> 0.11526389 | D86: =$C$80+(($Q$101*(1+D$80)*$C86)-$P$102)*(1-$P$137) -> 4662.734 | E86: =$C$80+(($Q$101*(1+E$80)*$C86)-$P$102)*(1-$P$137) -> 4741.9918 | F86: =$C$80+(($Q$101*(1+F$80)*$C86)-$P$102)*(1-$P$137) -> 4821.2496 | G86: =$C$80+(($Q$101*(1+G$80)*$C86)-$P$102)*(1-$P$137) -> 4900.5073 | H86: =$C$80+(($Q$101*(1+H$80)*$C86)-$P$102)*(1-$P$137) -> 4979.7651 | K86: =K85-$L$74 -> 135 | L86: =$K$80-(L$80-$N$80)*$P$101/365-($K86-$K$83)*$P$142/365 -> 1217.5838 | M86: =$K$80-(M$80-$N$80)*$P$101/365-($K86-$K$83)*$P$142/365 -> 1712.4615 | N86: =$K$80-(N$80-$N$80)*$P$101/365-($K86-$K$83)*$P$142/365 -> 2207.3393 | O86: =$K$80-(O$80-$N$80)*$P$101/365-($K86-$K$83)*$P$142/365 -> 2702.217 | P86: =$K$80-(P$80-$N$80)*$P$101/365-($K86-$K$83)*$P$142/365 -> 3197.0948
B98: Chart Data | P98: CY | Q98: PY
B99: Period | H99: =TEXT(Output!F2,"0")&"A" -> 2023A | I99: =TEXT(Output!G2,"0")&"A" -> 2024A | J99: =TEXT(Output!H2,"0")&"A" -> 2025A | K99: =TEXT(Output!I2,"0")&"F" -> 2026F | L99: =TEXT(Output!J2,"0")&"F" -> 2027F | M99: =TEXT(Output!K2,"0")&"F" -> 2028F | N99: =TEXT(Output!L2,"0")&"F" -> 2029F | O99: =TEXT(Output!M2,"0")&"F" -> 2030F | P99: =$P$2 -> 2026F | Q99: =IF(MATCH($P$2,$H$99:$O$99,0)=1,"n.a.",INDEX($H$99:$O$99,MATCH($P$2,$H$99:$O$99,0)-1)) -> 2025A
B100: Revenue Growth | H100: =Output!F156 -> 0 | I100: =Output!G156 -> -0.017471693 | J100: =Output!H156 -> -0.020006542 | K100: =Output!I156 -> 0.0047859742 | L100: =Output!J156 -> 0.015101075 | M100: =Output!K156 -> 0.005 | N100: =Output!L156 -> 0.020101563 | O100: =Output!M156 -> 0.02810235 | P100: =INDEX($H100:$O100,MATCH($P$2,$H$99:$O$99,0)) -> 0.0047859742 | Q100: =IF(MATCH($P$2,$H$99:$O$99,0)=1,"n.a.",INDEX($H100:$O100,MATCH($P$2,$H$99:$O$99,0)-1)) -> -0.020006542
B101: Revenue (CHF m) | H101: =Output!F9 -> 93351 | I101: =Output!G9 -> 91720 | J101: =Output!H9 -> 89885 | K101: =Output!I9 -> 90315.187 | L101: =Output!J9 -> 91679.044 | M101: =Output!K9 -> 92137.439 | N101: =Output!L9 -> 93989.546 | O101: =Output!M9 -> 96630.873 | P101: =INDEX($H101:$O101,MATCH($P$2,$H$99:$O$99,0)) -> 90315.187 | Q101: =IF(MATCH($P$2,$H$99:$O$99,0)=1,"n.a.",INDEX($H101:$O101,MATCH($P$2,$H$99:$O$99,0)-1)) -> 89885
B102: EBITDA (CHF m) | H102: =Output!F14 -> 17521 | I102: =Output!G14 -> 18306 | J102: =Output!H14 -> 15910 | K102: =Output!I14 -> 15828.991 | L102: =Output!J14 -> 16321.669 | M102: =Output!K14 -> 16209.005 | N102: =Output!L14 -> 16904.349 | O102: =Output!M14 -> 17663.153 | P102: =INDEX($H102:$O102,MATCH($P$2,$H$99:$O$99,0)) -> 15828.991 | Q102: =IF(MATCH($P$2,$H$99:$O$99,0)=1,"n.a.",INDEX($H102:$O102,MATCH($P$2,$H$99:$O$99,0)-1)) -> 15910
B103: Gross margin | H103: =Output!F83 -> 0.46087348 | I103: =Output!G83 -> 0.46936328 | J103: =Output!H83 -> 0.45826334 | K103: =Output!I83 -> 0.4603561 | L103: =Output!J83 -> 0.45842121 | M103: =Output!K83 -> 0.45154073 | N103: =Output!L83 -> 0.45247071 | O103: =Output!M83 -> 0.45384055 | P103: =INDEX($H103:$O103,MATCH($P$2,$H$99:$O$99,0)) -> 0.4603561 | Q103: =IF(MATCH($P$2,$H$99:$O$99,0)=1,"n.a.",INDEX($H103:$O103,MATCH($P$2,$H$99:$O$99,0)-1)) -> 0.45826334
B104: EBITDA margin | H104: =Output!F86 -> 0.18768947 | I104: =Output!G86 -> 0.1995857 | J104: =Output!H86 -> 0.17700395 | K104: =Output!I86 -> 0.17526389 | L104: =Output!J86 -> 0.17803053 | M104: =Output!K86 -> 0.17592203 | N104: =Output!L86 -> 0.17985351 | O104: =Output!M86 -> 0.18278995 | P104: =INDEX($H104:$O104,MATCH($P$2,$H$99:$O$99,0)) -> 0.17526389 | Q104: =IF(MATCH($P$2,$H$99:$O$99,0)=1,"n.a.",INDEX($H104:$O104,MATCH($P$2,$H$99:$O$99,0)-1)) -> 0.17700395
B105: EBIT margin | H105: =Output!F90 -> 0.15064648 | I105: =Output!G90 -> 0.16053205 | J105: =Output!H90 -> 0.13658564 | K105: =Output!I90 -> 0.13711372 | L105: =Output!J90 -> 0.13999046 | M105: =Output!K90 -> 0.13769029 | N105: =Output!L90 -> 0.14203662 | O105: =Output!M90 -> 0.14512975 | P105: =INDEX($H105:$O105,MATCH($P$2,$H$99:$O$99,0)) -> 0.13711372 | Q105: =IF(MATCH($P$2,$H$99:$O$99,0)=1,"n.a.",INDEX($H105:$O105,MATCH($P$2,$H$99:$O$99,0)-1)) -> 0.13658564
B106: Net profit margin | H106: =Output!F98 -> 0.12328738 | I106: =Output!G98 -> 0.1218273 | J106: =Output!H98 -> 0.10295377 | K106: =Output!I98 -> 0.10503585 | L106: =Output!J98 -> 0.10795114 | M106: =Output!K98 -> 0.10696944 | N106: =Output!L98 -> 0.11115228 | O106: =Output!M98 -> 0.11436212 | P106: =INDEX($H106:$O106,MATCH($P$2,$H$99:$O$99,0)) -> 0.10503585 | Q106: =IF(MATCH($P$2,$H$99:$O$99,0)=1,"n.a.",INDEX($H106:$O106,MATCH($P$2,$H$99:$O$99,0)-1)) -> 0.10295377
B107: Net profit (CHF m) | H107: =Output!F24 -> 11509 | I107: =Output!G24 -> 11174 | J107: =Output!H24 -> 9254 | K107: =Output!I24 -> 9486.3323 | L107: =Output!J24 -> 9896.8573 | M107: =Output!K24 -> 9855.89 | N107: =Output!L24 -> 10447.153 | O107: =Output!M24 -> 11050.912 | P107: =INDEX($H107:$O107,MATCH($P$2,$H$99:$O$99,0)) -> 9486.3323 | Q107: =IF(MATCH($P$2,$H$99:$O$99,0)=1,"n.a.",INDEX($H107:$O107,MATCH($P$2,$H$99:$O$99,0)-1)) -> 9254
B108: Return on equity | H108: =Output!F79 -> 0.31629428 | I108: =Output!G79 -> 0.30452675 | J108: =Output!H79 -> 0.27993224 | K108: =Output!I79 -> 0.27603888 | L108: =Output!J79 -> 0.27527672 | M108: =Output!K79 -> 0.26374556 | N108: =Output!L79 -> 0.2662567 | O108: =Output!M79 -> 0.27928286 | P108: =INDEX($H108:$O108,MATCH($P$2,$H$99:$O$99,0)) -> 0.27603888 | Q108: =IF(MATCH($P$2,$H$99:$O$99,0)=1,"n.a.",INDEX($H108:$O108,MATCH($P$2,$H$99:$O$99,0)-1)) -> 0.27993224
B109: Return on assets | H109: =Output!F80 -> 0.090944291 | I109: =Output!G80 -> 0.080236098 | J109: =Output!H80 -> 0.072779608 | K109: =Output!I80 -> 0.074576039 | L109: =Output!J80 -> 0.076819763 | M109: =Output!K80 -> 0.075324088 | N109: =Output!L80 -> 0.077938368 | O109: =Output!M80 -> 0.081396615 | P109: =INDEX($H109:$O109,MATCH($P$2,$H$99:$O$99,0)) -> 0.074576039 | Q109: =IF(MATCH($P$2,$H$99:$O$99,0)=1,"n.a.",INDEX($H109:$O109,MATCH($P$2,$H$99:$O$99,0)-1)) -> 0.072779608
B110: Return on invested capital | H110: =Output!F82 -> 0.13248468 | I110: =Output!G82 -> 0.11656413 | J110: =Output!H82 -> 0.10728797 | K110: =Output!I82 -> 0.10907626 | L110: =Output!J82 -> 0.11243851 | M110: =Output!K82 -> 0.11067382 | N110: =Output!L82 -> 0.11558303 | O110: =Output!M82 -> 0.11997637 | P110: =INDEX($H110:$O110,MATCH($P$2,$H$99:$O$99,0)) -> 0.10907626 | Q110: =IF(MATCH($P$2,$H$99:$O$99,0)=1,"n.a.",INDEX($H110:$O110,MATCH($P$2,$H$99:$O$99,0)-1)) -> 0.10728797
B111: DSO | H111: =Output!F118 -> 42.990166 | I111: =Output!G118 -> 44.773386 | J111: =Output!H118 -> 42.88552 | K111: =Output!I118 -> 42.820155 | L111: =Output!J118 -> 42.815892 | M111: =Output!K118 -> 42.318032 | N111: =Output!L118 -> 41.81601 | O111: =Output!M118 -> 41.811847 | P111: =INDEX($H111:$O111,MATCH($P$2,$H$99:$O$99,0)) -> 42.820155 | Q111: =IF(MATCH($P$2,$H$99:$O$99,0)=1,"n.a.",INDEX($H111:$O111,MATCH($P$2,$H$99:$O$99,0)-1)) -> 42.88552
B112: DSI | H112: =Output!F120 -> 86.274837 | I112: =Output!G120 -> 99.443189 | J112: =Output!H120 -> 96.043558 | K112: =Output!I120 -> 93 | L112: =Output!J120 -> 91 | M112: =Output!K120 -> 89 | N112: =Output!L120 -> 88 | O112: =Output!M120 -> 87 | P112: =INDEX($H112:$O112,MATCH($P$2,$H$99:$O$99,0)) -> 93 | Q112: =IF(MATCH($P$2,$H$99:$O$99,0)=1,"n.a.",INDEX($H112:$O112,MATCH($P$2,$H$99:$O$99,0)-1)) -> 96.043558
B113: DPO | H113: =Output!F122 -> 139.27555 | I113: =Output!G122 -> 163.5413 | J113: =Output!H122 -> 150.0882 | K113: =Output!I122 -> 150 | L113: =Output!J122 -> 150 | M113: =Output!K122 -> 150 | N113: =Output!L122 -> 150 | O113: =Output!M122 -> 150 | P113: =INDEX($H113:$O113,MATCH($P$2,$H$99:$O$99,0)) -> 150 | Q113: =IF(MATCH($P$2,$H$99:$O$99,0)=1,"n.a.",INDEX($H113:$O113,MATCH($P$2,$H$99:$O$99,0)-1)) -> 150.0882
B114: Cash Cycle | H114: =Output!F123 -> -10.010549 | I114: =Output!G123 -> -19.324723 | J114: =Output!H123 -> -11.159126 | K114: =Output!I123 -> -14.179845 | L114: =Output!J123 -> -16.184108 | M114: =Output!K123 -> -18.681968 | N114: =Output!L123 -> -20.18399 | O114: =Output!M123 -> -21.188153 | P114: =INDEX($H114:$O114,MATCH($P$2,$H$99:$O$99,0)) -> -14.179845 | Q114: =IF(MATCH($P$2,$H$99:$O$99,0)=1,"n.a.",INDEX($H114:$O114,MATCH($P$2,$H$99:$O$99,0)-1)) -> -11.159126
B116: Operating cash flow | H116: =Output!F36 -> 15941 | I116: =Output!G36 -> 16675 | J116: =Output!H36 -> 15904 | K116: =Output!I36 -> 13733.402 | L116: =Output!J36 -> 14174.144 | M116: =Output!K36 -> 14255.556 | N116: =Output!L36 -> 14599.324 | O116: =Output!M36 -> 14942.689 | P116: =INDEX($H116:$O116,MATCH($P$2,$H$99:$O$99,0)) -> 13733.402 | Q116: =IF(MATCH($P$2,$H$99:$O$99,0)=1,"n.a.",INDEX($H116:$O116,MATCH($P$2,$H$99:$O$99,0)-1)) -> 15904
...

Sheet Output
B2: ="Nestlé S.A. | CHF millions | Scenario: "&INDEX(Input!$B$12:$B$14,ScenarioSwitch) -> Nestlé S.A. | CHF millions | Scenario: Base Case | F2: =G2-1 -> 2023 | G2: =H2-1 -> 2024 | H2: =I2-1 -> 2025 | I2: =Input!$I$2 -> 2026 | J2: =I2+1 -> 2027 | K2: =J2+1 -> 2028 | L2: =K2+1 -> 2029 | M2: =L2+1 -> 2030
B4: INCOME STATEMENT
B6: =Input!$B$131 -> All figures in CHF millions unless stated | F6: =F$2 -> 2023 | G6: =G$2 -> 2024 | H6: =H$2 -> 2025 | I6: =I$2 -> 2026 | J6: =J$2 -> 2027 | K6: =K$2 -> 2028 | L6: =L$2 -> 2029 | M6: =M$2 -> 2030
B7: =CONCATENATE("Model Running: ",INDEX(Input!$B$12:$B$14,Input!$D$6)," Drivers") -> Model Running: Base Case Drivers
B9: Revenue | F9: =Model!F255+Model!F256 -> 93351 | G9: =Model!G255+Model!G256 -> 91720 | H9: =Model!H255+Model!H256 -> 89885 | I9: =Model!I255+Model!I256 -> 90315.187 | J9: =Model!J255+Model!J256 -> 91679.044 | K9: =Model!K255+Model!K256 -> 92137.439 | L9: =Model!L255+Model!L256 -> 93989.546 | M9: =Model!M255+Model!M256 -> 96630.873
B10: Cost of Good Sold | F10: =Model!F257 -> -50328 | G10: =Model!G257 -> -48670 | H10: =Model!H257 -> -48694 | I10: =Model!I257 -> -48738.04 | J10: =Model!J257 -> -49651.426 | K10: =Model!K257 -> -50533.633 | L10: =Model!L257 -> -51462.029 | M10: =Model!M257 -> -52775.864
B11: Gross Profit | F11: =SUM(F9:F10) -> 43023 | G11: =SUM(G9:G10) -> 43050 | H11: =SUM(H9:H10) -> 41191 | I11: =SUM(I9:I10) -> 41577.147 | J11: =SUM(J9:J10) -> 42027.618 | K11: =SUM(K9:K10) -> 41603.806 | L11: =SUM(L9:L10) -> 42527.517 | M11: =SUM(M9:M10) -> 43855.009
B13: SG&A Expenses | F13: =SUM(Model!F258:F262)+SUM(Model!F265:F266)+Model!F288 -> -25502 | G13: =SUM(Model!G258:G262)+SUM(Model!G265:G266)+Model!G288 -> -24744 | H13: =SUM(Model!H258:H262)+SUM(Model!H265:H266)+Model!H288 -> -25281 | I13: =SUM(Model!I258:I262)+SUM(Model!I265:I266)+Model!I288 -> -25748.156 | J13: =SUM(Model!J258:J262)+SUM(Model!J265:J266)+Model!J288 -> -25705.949 | K13: =SUM(Model!K258:K262)+SUM(Model!K265:K266)+Model!K288 -> -25394.802 | L13: =SUM(Model!L258:L262)+SUM(Model!L265:L266)+Model!L288 -> -25623.167 | M13: =SUM(Model!M258:M262)+SUM(Model!M265:M266)+Model!M288 -> -26191.856
B14: EBITDA | F14: =F11+F13 -> 17521 | G14: =G11+G13 -> 18306 | H14: =H11+H13 -> 15910 | I14: =I11+I13 -> 15828.991 | J14: =J11+J13 -> 16321.669 | K14: =K11+K13 -> 16209.005 | L14: =L11+L13 -> 16904.349 | M14: =M11+M13 -> 17663.153
B16: Depreciation | F16: =Model!F288*-1 -> -3458 | G16: =Model!G288*-1 -> -3582 | H16: =Model!H288*-1 -> -3633 | I16: =Model!I288*-1 -> -3445.54 | J16: =Model!J288*-1 -> -3487.477 | K16: =Model!K288*-1 -> -3522.5745 | L16: =Model!L288*-1 -> -3554.3919 | M16: =Model!M288*-1 -> -3639.1378
B17: EBIT | F17: =F14+F16 -> 14063 | G17: =G14+G16 -> 14724 | H17: =H14+H16 -> 12277 | I17: =I14+I16 -> 12383.451 | J17: =J14+J16 -> 12834.192 | K17: =K14+K16 -> 12686.43 | L17: =L14+L16 -> 13349.957 | M17: =M14+M16 -> 14024.015
B19: Net Interest | F19: =SUM(Model!F269:F270) -> -1360 | G19: =SUM(Model!G269:G270) -> -1485 | H19: =SUM(Model!H269:H270) -> -1526 | I19: =SUM(Model!I269:I270) -> -1521.958 | J19: =SUM(Model!J269:J270) -> -1497.622 | K19: =SUM(Model!K269:K270) -> -1467.4329 | L19: =SUM(Model!L269:L270) -> -1441.2936 | M19: =SUM(Model!M269:M270) -> -1413.5106
B20: EBT | F20: =F17+F19 -> 12703 | G20: =G17+G19 -> 13239 | H20: =H17+H19 -> 10751 | I20: =I17+I19 -> 10861.493 | J20: =J17+J19 -> 11336.57 | K20: =K17+K19 -> 11218.998 | L20: =L17+L19 -> 11908.664 | M20: =M17+M19 -> 12610.504
B22: Taxes | F22: =Model!F273 -> -2314 | G22: =Model!G273 -> -3314 | H22: =Model!H273 -> -2640 | I22: =Model!I273 -> -2552.4509 | J22: =Model!J273 -> -2664.0938 | K22: =Model!K273 -> -2636.4644 | L22: =Model!L273 -> -2798.536 | M22: =Model!M273 -> -2963.4685
B23: Income from associates and joint ventures | F23: =Model!F274 -> 1120 | G23: =Model!G274 -> 1249 | H23: =Model!H274 -> 1143 | I23: =Model!I274 -> 1177.29 | J23: =Model!J274 -> 1224.3816 | K23: =Model!K274 -> 1273.3569 | L23: =Model!L274 -> 1337.0247 | M23: =Model!M274 -> 1403.8759
B24: Net Profit | F24: =SUM(F20:F23) -> 11509 | G24: =SUM(G20:G23) -> 11174 | H24: =SUM(H20:H23) -> 9254 | I24: =SUM(I20:I23) -> 9486.3323 | J24: =SUM(J20:J23) -> 9896.8573 | K24: =SUM(K20:K23) -> 9855.89 | L24: =SUM(L20:L23) -> 10447.153 | M24: =SUM(M20:M23) -> 11050.912
B26: NCI | F26: =Model!F277 -> 300 | G26: =Model!G277 -> 290 | H26: =Model!H277 -> 221 | I26: =Model!I277 -> 237.15831 | J26: =Model!J277 -> 247.42143 | K26: =Model!K277 -> 246.39725 | L26: =Model!L277 -> 261.17881 | M26: =Model!M277 -> 276.27279
B27: Parent | F27: =Model!F278 -> 11209 | G27: =Model!G278 -> 10884 | H27: =Model!H278 -> 9033 | I27: =Model!I278 -> 9249.174 | J27: =Model!J278 -> 9649.4359 | K27: =Model!K278 -> 9609.4927 | L27: =Model!L278 -> 10185.974 | M27: =Model!M278 -> 10774.639
B31: CASHFLOW STATEMENT
B33: =Input!$B$131 -> All figures in CHF millions unless stated | F33: =F$2 -> 2023 | G33: =G$2 -> 2024 | H33: =H$2 -> 2025 | I33: =I$2 -> 2026 | J33: =J$2 -> 2027 | K33: =K$2 -> 2028 | L33: =L$2 -> 2029 | M33: =M$2 -> 2030
B34: =CONCATENATE("Model Running: ",INDEX(Input!$B$12:$B$14,Input!$D$6)," Drivers") -> Model Running: Base Case Drivers
B36: Operating | F36: =Model!F302 -> 15941 | G36: =Model!G302 -> 16675 | H36: =Model!H302 -> 15904 | I36: =Model!I302 -> 13733.402 | J36: =Model!J302 -> 14174.144 | K36: =Model!K302 -> 14255.556 | L36: =Model!L302 -> 14599.324 | M36: =Model!M302 -> 14942.689
B37: Investing | F37: =Model!F313 -> -6196 | G37: =Model!G313 -> -8624 | H37: =Model!H313 -> -4367 | I37: =Model!I313 -> -4766.6848 | J37: =Model!J313 -> -4746.8986 | K37: =Model!K313 -> -4770.6331 | L37: =Model!L313 -> -4819.2569 | M37: =Model!M313 -> -4954.1961
B38: Financing | F38: =Model!F324 -> -9758 | G38: =Model!G324 -> -7362 | H38: =Model!H324 -> -12065 | I38: =Model!I324 -> -9335.4442 | J38: =Model!J324 -> -8877.3407 | K38: =Model!K324 -> -8439.3522 | L38: =Model!L324 -> -8017.6604 | M38: =Model!M324 -> -10152.276
B42: BALANCE SHEET
B44: =Input!$B$131 -> All figures in CHF millions unless stated | F44: =F$2 -> 2023 | G44: =G$2 -> 2024 | H44: =H$2 -> 2025 | I44: =I$2 -> 2026 | J44: =J$2 -> 2027 | K44: =K$2 -> 2028 | L44: =L$2 -> 2029 | M44: =M$2 -> 2030
B45: =CONCATENATE("Model Running: ",INDEX(Input!$B$12:$B$14,Input!$D$6)," Drivers") -> Model Running: Base Case Drivers
B47: Cash & Equivalents | F47: =Model!F341 -> 4816 | G47: =Model!G341 -> 5556 | H47: =Model!H341 -> 4579 | I47: =Model!I341 -> 4210.2724 | J47: =Model!J341 -> 4760.1772 | K47: =Model!K341 -> 5805.748 | L47: =Model!L341 -> 7568.1546 | M47: =Model!M341 -> 7404.3711
B48: Trade Receivable | F48: =Model!F344 -> 10995 | G48: =Model!G344 -> 11251 | H48: =Model!H344 -> 10561 | I48: =Model!I344 -> 10595.371 | J48: =Model!J344 -> 10754.301 | K48: =Model!K344 -> 10682.398 | L48: =Model!L344 -> 10767.857 | M48: =Model!M344 -> 11069.357
B49: Inventory | F49: =Model!F343 -> 11896 | G49: =Model!G343 -> 13260 | H49: =Model!H343 -> 12813 | I49: =Model!I343 -> 12418.185 | J49: =Model!J343 -> 12378.849 | K49: =Model!K343 -> 12321.899 | L49: =Model!L343 -> 12407.284 | M49: =Model!M343 -> 12579.452
B50: Other Current Assets | F50: =Model!F342+Model!F345+Model!F346+Model!F347+Model!F348 -> 3150 | G50: =Model!G342+Model!G345+Model!G346+Model!G347+Model!G348 -> 5121 | H50: =Model!H342+Model!H345+Model!H346+Model!H347+Model!H348 -> 4016 | I50: =Model!I342+Model!I345+Model!I346+Model!I347+Model!I348 -> 4029.8079 | J50: =Model!J342+Model!J345+Model!J346+Model!J347+Model!J348 -> 4037.2001 | K50: =Model!K342+Model!K345+Model!K346+Model!K347+Model!K348 -> 4039.7011 | L50: =Model!L342+Model!L345+Model!L346+Model!L347+Model!L348 -> 4049.7551 | M50: =Model!M342+Model!M345+Model!M346+Model!M347+Model!M348 -> 4064.1122
B51: Total Current Assets | F51: =SUM(F47:F50) -> 30857 | G51: =SUM(G47:G50) -> 35188 | H51: =SUM(H47:H50) -> 31969 | I51: =SUM(I47:I50) -> 31253.637 | J51: =SUM(J47:J50) -> 31930.527 | K51: =SUM(K47:K50) -> 32849.746 | L51: =SUM(L47:L50) -> 34793.05 | M51: =SUM(M47:M50) -> 35117.293
B53: PPE | F53: =Model!F352 -> 30467 | G53: =Model!G352 -> 33706 | H53: =Model!H352 -> 32549 | I53: =Model!I352 -> 34027.226 | J53: =Model!J352 -> 35444.623 | K53: =Model!K352 -> 36854.096 | L53: =Model!L352 -> 38231.02 | M53: =Model!M352 -> 39659.058
B54: Other Non-Current Assets | F54: =SUM(Model!F353:F359) -> 65226 | G54: =SUM(Model!G353:G359) -> 70370 | H54: =SUM(Model!H353:H359) -> 62633 | I54: =SUM(Model!I353:I359) -> 61922.626 | J54: =SUM(Model!J353:J359) -> 61457.027 | K54: =SUM(Model!K353:K359) -> 61142.614 | L54: =SUM(Model!L353:L359) -> 61019.698 | M54: =SUM(Model!M353:M359) -> 60989.88
B55: Total Non-Current Assets | F55: =SUM(F53:F54) -> 95693 | G55: =SUM(G53:G54) -> 104076 | H55: =SUM(H53:H54) -> 95182 | I55: =SUM(I53:I54) -> 95949.852 | J55: =SUM(J53:J54) -> 96901.65 | K55: =SUM(K53:K54) -> 97996.71 | L55: =SUM(L53:L54) -> 99250.718 | M55: =SUM(M53:M54) -> 100648.94
B56: Total Assets | F56: =F51+F55 -> 126550 | G56: =G51+G55 -> 139264 | H56: =H51+H55 -> 127151 | I56: =I51+I55 -> 127203.49 | J56: =J51+J55 -> 128832.18 | K56: =K51+K55 -> 130846.46 | L56: =L51+L55 -> 134043.77 | M56: =M51+M55 -> 135766.23
B58: Trade Payable | F58: =Model!F366 -> 19204 | G58: =Model!G366 -> 21807 | H58: =Model!H366 -> 20023 | I58: =Model!I366 -> 20029.331 | J58: =Model!J366 -> 20404.696 | K58: =Model!K366 -> 20767.246 | L58: =Model!L366 -> 21148.779 | M58: =Model!M366 -> 21688.711
B59: Other Current Liabilities | F59: =SUM(Model!F364:F365)+SUM(Model!F367:F371) -> 17880 | G59: =SUM(Model!G364:G365)+SUM(Model!G367:G371) -> 21056 | H59: =SUM(Model!H364:H365)+SUM(Model!H367:H371) -> 20671 | I59: =SUM(Model!I364:I365)+SUM(Model!I367:I371) -> 20170.147 | J59: =SUM(Model!J364:J365)+SUM(Model!J367:J371) -> 20156.854 | K59: =SUM(Model!K364:K365)+SUM(Model!K367:K371) -> 20253.534 | L59: =SUM(Model!L364:L365)+SUM(Model!L367:L371) -> 20608.524 | M59: =SUM(Model!M364:M365)+SUM(Model!M367:M371) -> 20869.484
B60: Total Current Liabilities | F60: =SUM(F58:F59) -> 37084 | G60: =SUM(G58:G59) -> 42863 | H60: =SUM(H58:H59) -> 40694 | I60: =SUM(I58:I59) -> 40199.478 | J60: =SUM(J58:J59) -> 40561.55 | K60: =SUM(K58:K59) -> 41020.781 | L60: =SUM(L58:L59) -> 41757.303 | M60: =SUM(M58:M59) -> 42558.196
B62: Financial Debt | F62: =Model!F375 -> 45825 | G62: =Model!G375 -> 51697 | H62: =Model!H375 -> 46246 | I62: =Model!I375 -> 45355.968 | J62: =Model!J375 -> 44902.408 | K62: =Model!K375 -> 44902.408 | L62: =Model!L375 -> 45351.432 | M62: =Model!M375 -> 45804.947
...

Sheet Input
B2: ="Nestlé S.A. | CHF millions | Scenario: "&INDEX(Input!$B$12:$B$14,Input!$D$6) -> Nestlé S.A. | CHF millions | Scenario: Base Case | I2: =F173 -> 2026 | J2: =I2+1 -> 2027 | K2: =J2+1 -> 2028 | L2: =K2+1 -> 2029 | M2: =L2+1 -> 2030 | O2: Justification / basis of assumption
B4: Growth & Margin Drivers
C6: Model Running: | D6: =Dashboard!$F$2 -> 2
B8: All figures in CHF millions unless stated | I8: =I$2 -> 2026 | J8: =J$2 -> 2027 | K8: =K$2 -> 2028 | L8: =L$2 -> 2029 | M8: =M$2 -> 2030
B10: Sales growth, % YoY | I10: =INDEX(I12:I14,$D$6) -> 0.005 | J10: =INDEX(J12:J14,$D$6) -> 0.015 | K10: =INDEX(K12:K14,$D$6) -> 0.005 | L10: =INDEX(L12:L14,$D$6) -> 0.02 | M10: =INDEX(M12:M14,$D$6) -> 0.028
B12: Best Case | I12: 0.025 | J12: 0.035 | K12: 0.04 | L12: 0.045 | M12: 0.05 | O12: Best Case: reported sales growth converges toward the organic growth guidance (3–4% for 2026) as the c.3% FX headwind from a strong CHF and the 2025–26 portfolio exits (Waters JV, VMS, ice cream) roll off, building to 5% by 2030. Source: Nestlé H1 2026 results and FY2026 guidance.
B13: Base Case | I13: 0.005 | J13: 0.015 | K13: 0.005 | L13: 0.02 | M13: 0.028 | O13: Base Case: 2026 +0.5% = organic growth guidance of 3–4% less a c.3% FX headwind at spot rates (H1 2026 guidance); 2027 +1.5% as FX normalises; 2028 slows under an assumed mild global slowdown; 2029–30 returns toward the organic trend (2.0–2.8%). The Waters deconsolidation into the Peranel JV (FY2025 sales CHF 3.5bn, closing H1 2027) is not modelled separately and would lower 2027 reported sales by up to c.4pp.
B14: Worst Case | I14: -0.015 | J14: -0.01 | K14: -0.055 | L14: -0.03 | M14: 0.005 | O14: Worst Case: a demand and macro shock in 2028–29 (–5.5% and –3.0%), sized on the roughly ten-year cadence of past global stress events (1998, 2008, 2020). Consumer staples are assumed to decline less than cyclical sectors, with stabilisation in 2030.
B17: Other revenue, % of sales | I17: =INDEX(I19:I21,$D$6) -> 0.0042 | J17: =INDEX(J19:J21,$D$6) -> 0.0043 | K17: =INDEX(K19:K21,$D$6) -> 0.0043 | L17: =INDEX(L19:L21,$D$6) -> 0.0044 | M17: =INDEX(M19:M21,$D$6) -> 0.0045
B19: 1 | I19: 0.0042 | J19: 0.0044 | K19: 0.0046 | L19: 0.0048 | M19: 0.005 | O19: Other revenue (royalty and licensing-type income) as % of sales. FY23–25 range 0.38–0.44%; the Best Case trends gently upward with stronger sales momentum.
B20: 2 | I20: 0.0042 | J20: 0.0043 | K20: 0.0043 | L20: 0.0044 | M20: 0.0045 | O20: Held at 0.42–0.45% of sales, close to the FY2025 level (0.44%) and slightly above the FY23–25 average (0.41%).
B21: 3 | I21: 0.0038 | J21: 0.0035 | K21: 0.003 | L21: 0.0033 | M21: 0.0036 | O21: Compressed during the 2028–29 downturn on lower royalty and licensing volumes, recovering partially by 2030.
B24: COGS | I24: =INDEX(I26:I28,$D$6) -> 0.00090441985 | J24: =INDEX(J26:J28,$D$6) -> 0.018740719 | K24: =INDEX(K26:K28,$D$6) -> 0.017768006 | L24: =INDEX(L26:L28,$D$6) -> 0.018371853 | M24: =INDEX(M26:M28,$D$6) -> 0.025530179
B26: Best Case | I26: 0.015082154 | J26: 0.028739312 | K26: 0.030626201 | L26: 0.034982241 | M26: 0.035676958 | O26: COGS is projected as a growth rate on the prior year and is the main lever for the gross-margin path. In the Best Case COGS grows slower than sales, supported by 'Fuel for Growth' procurement savings (CHF 3bn gross savings target by end-2027) and easing cocoa and coffee costs.
B27: Base Case | I27: 0.00090441985 | J27: 0.018740719 | K27: 0.017768006 | L27: 0.018371853 | M27: 0.025530179 | O27: Calibrated so that the EBITDA margin moves from 17.5% (2026) to 18.3% (2030), recovering above the FY2025 level (17.7%) but staying below FY2024 (20.0%), as coffee and cocoa cost relief and 'Fuel for Growth' savings are partly reinvested.
B28: Worst Case | I28: -0.010364991 | J28: 0.00033932446 | K28: -0.052572217 | L28: -0.0018388641 | M28: -5.4555294e-05 | O28: In the 2028 shock year COGS falls less than sales (–5.3% vs –5.5%): input costs and FX stay elevated while volumes soften, the typical operating-deleverage pattern for consumer staples in a downturn.
B31: Distribution expenses | I31: =INDEX(I33:I35,$D$6) -> 0.081 | J31: =INDEX(J33:J35,$D$6) -> 0.0805 | K31: =INDEX(K33:K35,$D$6) -> 0.08 | L31: =INDEX(L33:L35,$D$6) -> 0.0795 | M31: =INDEX(M33:M35,$D$6) -> 0.079
B33: Best Case | I33: 0.08 | J33: 0.0785 | K33: 0.077 | L33: 0.0755 | M33: 0.074 | O33: Distribution costs as % of sales continue the FY23–25 decline (8.3% to 8.2%) through logistics and network efficiencies, reaching 7.4% by 2030.
B34: Base Case | I34: 0.081 | J34: 0.0805 | K34: 0.08 | L34: 0.0795 | M34: 0.079 | O34: Gradual improvement from the FY2025 level (8.2%) to 7.9% by 2030 from ongoing logistics and network efficiency.
B35: Worst Case | I35: 0.083 | J35: 0.085 | K35: 0.09 | L35: 0.087 | M35: 0.084 | O35: Rises to 9.0% in 2028 as freight costs increase and lower volumes absorb fixed distribution costs, then partially normalises.
B38: Marketing & administration expenses | I38: =INDEX(I40:I42,$D$6) -> 0.2 | J38: =INDEX(J40:J42,$D$6) -> 0.201 | K38: =INDEX(K40:K42,$D$6) -> 0.201 | L38: =INDEX(L40:L42,$D$6) -> 0.202 | M38: =INDEX(M40:M42,$D$6) -> 0.203
B40: Best Case | I40: 0.201 | J40: 0.203 | K40: 0.205 | L40: 0.206 | M40: 0.208 | O40: Includes a deliberate step-up in advertising and promotion, in line with management's stated intent to lift A&P toward c.9% of sales, within a Marketing & Administration total that has run at 19–20% of sales; reaches 20.8% by 2030.
B41: Base Case | I41: 0.2 | J41: 0.201 | K41: 0.201 | L41: 0.202 | M41: 0.203 | O41: Modest reinvestment from 20.0% to 20.3% of sales, broadly in line with the FY2025 level (20.0%).
B42: Worst Case | I42: 0.197 | J42: 0.202 | K42: 0.213 | L42: 0.205 | M42: 0.199 | O42: Rises to 21.3% in 2028: overheads are less flexible than marketing spend, so the ratio increases even as A&P is reduced; it partially normalises thereafter.
B45: Other trading income | I45: =INDEX(I47:I49,$D$6) -> 0.0014 | J45: =INDEX(J47:J49,$D$6) -> 0.0014 | K45: =INDEX(K47:K49,$D$6) -> 0.0013 | L45: =INDEX(L47:L49,$D$6) -> 0.0014 | M45: =INDEX(M47:M49,$D$6) -> 0.0014
B47: Best Case | I47: 0.0016 | J47: 0.0017 | K47: 0.0017 | L47: 0.0018 | M47: 0.0018 | O47: Small and historically volatile line (FY23–25: 0.14–0.15% of sales); the Best Case is slightly higher.
B48: Base Case | I48: 0.0014 | J48: 0.0014 | K48: 0.0013 | L48: 0.0014 | M48: 0.0014 | O48: Held near the FY23–25 average.
B49: Worst Case | I49: 0.0008 | J49: 0.0006 | K49: 0.0005 | L49: 0.0007 | M49: 0.0009 | O49: Compressed during the 2028–29 downturn.
B52: Other trading expenses | I52: =INDEX(I54:I56,$D$6) -> 0.024 | J52: =INDEX(J54:J56,$D$6) -> 0.019 | K52: =INDEX(K54:K56,$D$6) -> 0.015 | L52: =INDEX(L54:L56,$D$6) -> 0.0115 | M52: =INDEX(M54:M56,$D$6) -> 0.0095
B54: Best Case | I54: 0.022 | J54: 0.017 | K54: 0.013 | L54: 0.01 | M54: 0.0085 | O54: Elevated in 2026–27 by 'Fuel for Growth' restructuring and impairment-type charges (c.16,000 role reductions by end-2027, announced in Q4 2025), fading from 2028 as the programme completes; the Best Case assumes faster execution.
B55: Base Case | I55: 0.024 | J55: 0.019 | K55: 0.015 | L55: 0.0115 | M55: 0.0095 | O55: H1 2026 other trading expenses ran at 1.9% of sales (restructuring and net other trading items CHF 0.8bn vs CHF 0.4bn in H1 2025) as 'Fuel for Growth' restructuring accelerated; 2.4% for the full year allows for H2 phasing, declining to 0.95% of sales by 2030 as the programme completes.
B56: Worst Case | I56: 0.027 | J56: 0.025 | K56: 0.034 | L56: 0.021 | M56: 0.016 | O56: Adds further impairment and restructuring charges in the 2028 shock year (3.4% of sales) on top of the ongoing programme, before receding.
B59: Other operating income | I59: =INDEX(I61:I63,$D$6) -> 0.003 | J59: =INDEX(J61:J63,$D$6) -> 0.0028 | K59: =INDEX(K61:K63,$D$6) -> 0.0027 | L59: =INDEX(L61:L63,$D$6) -> 0.0028 | M59: =INDEX(M61:M63,$D$6) -> 0.0028
B61: Best Case | I61: 0.0035 | J61: 0.0035 | K61: 0.0035 | L61: 0.0034 | M61: 0.0034 | O61: Historically volatile, disposal-gain-type line (FY23–25: 0.28–0.52% of sales); the Best Case assumes slightly more portfolio gains.
B62: Base Case | I62: 0.003 | J62: 0.0028 | K62: 0.0027 | L62: 0.0028 | M62: 0.0028 | O62: Held near the FY2025 level (0.28% of sales), below the FY23–25 average (0.37%), which included higher disposal gains in 2024.
B63: Worst Case | I63: 0.0015 | J63: 0.0012 | K63: 0.001 | L63: 0.0012 | M63: 0.0015 | O63: Compressed in the downturn as fewer disposal gains are realised.
B66: Other operating expenses | I66: =INDEX(I68:I70,$D$6) -> 0.006 | J66: =INDEX(J68:J70,$D$6) -> 0.0055 | K66: =INDEX(K68:K70,$D$6) -> 0.0052 | L66: =INDEX(L68:L70,$D$6) -> 0.005 | M66: =INDEX(M68:M70,$D$6) -> 0.0048
B68: Best Case | I68: 0.005 | J68: 0.0045 | K68: 0.0042 | L68: 0.004 | M68: 0.0038 | O68: Historically 0.42–0.81% of sales (FY23–25); the Best Case trends lower.
B69: Base Case | I69: 0.006 | J69: 0.0055 | K69: 0.0052 | L69: 0.005 | M69: 0.0048 | O69: 0.60% of sales in 2026 easing to 0.48% by 2030, below FY2025 (0.73%, incl. infant-formula inventory write-offs). Excludes the CHF 1.3bn one-off non-cash write-down on assets held for sale booked in H1 2026, so reported 2026 net profit will be lower than modelled; the non-cash share of this line is added back in the cash flow via row 168.
B70: Worst Case | I70: 0.0085 | J70: 0.01 | K70: 0.0135 | L70: 0.0105 | M70: 0.0085 | O70: Rises to 1.35% of sales in the 2028 trough, then recedes.
...

Sheet Model
B2: =Input!$B$2 -> Nestlé S.A. | CHF millions | Scenario: Base Case | F2: =G2-1 -> 2023 | G2: =H2-1 -> 2024 | H2: =I2-1 -> 2025 | I2: =Input!$I$2 -> 2026 | J2: =I2+1 -> 2027 | K2: =J2+1 -> 2028 | L2: =K2+1 -> 2029 | M2: =L2+1 -> 2030
B4: Growth & Margin Drivers
B6: =Input!$B$131 -> All figures in CHF millions unless stated | F6: =F$2 -> 2023 | G6: =G$2 -> 2024 | H6: =H$2 -> 2025 | I6: =I$2 -> 2026 | J6: =J$2 -> 2027 | K6: =K$2 -> 2028 | L6: =L$2 -> 2029 | M6: =M$2 -> 2030
B7: =CONCATENATE("Model Running: ",INDEX(Input!$B$12:$B$14,Input!$D$6)," Drivers") -> Model Running: Base Case Drivers
B9: Sales growth | G9: -0.0176778 | H9: -0.020404142 | I9: =Input!I$10 -> 0.005 | J9: =Input!J$10 -> 0.015 | K9: =Input!K$10 -> 0.005 | L9: =Input!L$10 -> 0.02 | M9: =Input!M$10 -> 0.028
B10: Other revenue | F10: 0.0037957806 | G10: 0.0040063927 | H10: 0.004413901 | I10: =Input!I$17 -> 0.0042 | J10: =Input!J$17 -> 0.0043 | K10: =Input!K$17 -> 0.0043 | L10: =Input!L$17 -> 0.0044 | M10: =Input!M$17 -> 0.0045
B11: Cost of goods sold | G11: -0.032943888 | H11: 0.00049311691 | I11: =Input!I$24 -> 0.00090441985 | J11: =Input!J$24 -> 0.018740719 | K11: =Input!K$24 -> 0.017768006 | L11: =Input!L$24 -> 0.018371853 | M11: =Input!M$24 -> 0.025530179
B12: Distribution expenses | F12: 0.083496419 | G12: 0.082831622 | H12: 0.081640407 | I12: =Input!I$31 -> 0.081 | J12: =Input!J$31 -> 0.0805 | K12: =Input!K$31 -> 0.08 | L12: =Input!L$31 -> 0.0795 | M12: =Input!M$31 -> 0.079
B13: Marketing & administration expenses | F13: 0.18870298 | G13: 0.19826171 | H13: 0.19983238 | I13: =Input!I$38 -> 0.2 | J13: =Input!J$38 -> 0.201 | K13: =Input!K$38 -> 0.201 | L13: =Input!L$38 -> 0.202 | M13: =Input!M$38 -> 0.203
B14: R&D costs | F14: 0.017806835 | G14: 0.018247696 | H14: 0.01802436 | I14: =Input!$F$183 -> 0.018 | J14: =Input!$F$183 -> 0.018 | K14: =Input!$F$183 -> 0.018 | L14: =Input!$F$183 -> 0.018 | M14: =Input!$F$183 -> 0.018
B15: Other trading income | F15: 0.0014193854 | G15: 0.0013573571 | H15: 0.0015085484 | I15: =Input!I$45 -> 0.0014 | J15: =Input!J$45 -> 0.0014 | K15: =Input!K$45 -> 0.0013 | L15: =Input!L$45 -> 0.0014 | M15: =Input!M$45 -> 0.0014
B16: Other trading expenses | F16: 0.017903611 | G16: 0.013080982 | H16: 0.020661526 | I16: =Input!I$52 -> 0.024 | J16: =Input!J$52 -> 0.019 | K16: =Input!K$52 -> 0.015 | L16: =Input!L$52 -> 0.0115 | M16: =Input!M$52 -> 0.0095
B17: Other operating income | F17: 0.00320437 | G17: 0.005188607 | H17: 0.0028271315 | I17: =Input!I$59 -> 0.003 | J17: =Input!J$59 -> 0.0028 | K17: =Input!K$59 -> 0.0027 | L17: =Input!L$59 -> 0.0028 | M17: =Input!M$59 -> 0.0028
B18: Other operating expenses | F18: 0.0081184542 | G18: 0.004192482 | H18: 0.0072745558 | I18: =Input!I$66 -> 0.006 | J18: =Input!J$66 -> 0.0055 | K18: =Input!K$66 -> 0.0052 | L18: =Input!L$66 -> 0.005 | M18: =Input!M$66 -> 0.0048
B19: Effective tax rate | F19: 0.18216169 | G19: 0.25032102 | H19: 0.24555855 | I19: =Input!$M$173 -> 0.235 | J19: =Input!$M$173 -> 0.235 | K19: =Input!$M$173 -> 0.235 | L19: =Input!$M$173 -> 0.235 | M19: =Input!$M$173 -> 0.235
B20: Income from associates & JV | G20: 0.11517857 | H20: -0.084867894 | I20: =Input!I$73 -> 0.03 | J20: =Input!J$73 -> 0.04 | K20: =Input!K$73 -> 0.04 | L20: =Input!L$73 -> 0.05 | M20: =Input!M$73 -> 0.05
B21: Non-controlling interests | F21: 0.026066557 | G21: 0.025953105 | H21: 0.023881565 | I21: =Input!$F$182 -> 0.025 | J21: =Input!$F$182 -> 0.025 | K21: =Input!$F$182 -> 0.025 | L21: =Input!$F$182 -> 0.025 | M21: =Input!$F$182 -> 0.025
B22: Non-cash share of other trading & operating expenses | F22: =IFERROR(F289/-(F262+F266),0) -> 0.26735537 | G22: =IFERROR(G289/-(G262+G266),0) -> 0.36755387 | H22: =IFERROR(H289/-(H262+H266),0) -> 0.3692 | I22: =Input!I$168 -> 0.35 | J22: =Input!J$168 -> 0.35 | K22: =Input!K$168 -> 0.35 | L22: =Input!L$168 -> 0.35 | M22: =Input!M$168 -> 0.35
B25: Equity & Dividend Drivers
B27: =Input!$B$131 -> All figures in CHF millions unless stated | F27: =F$2 -> 2023 | G27: =G$2 -> 2024 | H27: =H$2 -> 2025 | I27: =I$2 -> 2026 | J27: =J$2 -> 2027 | K27: =K$2 -> 2028 | L27: =L$2 -> 2029 | M27: =M$2 -> 2030
B28: =CONCATENATE("Model Running: ",INDEX(Input!$B$12:$B$14,Input!$D$6)," Drivers") -> Model Running: Base Case Drivers
B30: Dividend payout ratio, % of net profit (parent) | F30: 0.6984566 | G30: 0.71811834 | H30: 0.86892505 | I30: =Input!I$134 -> 0.865 | J30: =Input!J$134 -> 0.842 | K30: =Input!K$134 -> 0.859 | L30: =Input!L$134 -> 0.823 | M30: =Input!M$134 -> 0.79
B31: Dividends to NCI, % of NCI profit | F31: 1.0766667 | G31: 0.6 | H31: 0.77828054 | I31: =Input!I$155 -> 0.75 | J31: =Input!J$155 -> 0.75 | K31: =Input!K$155 -> 0.75 | L31: =Input!L$155 -> 0.75 | M31: =Input!M$155 -> 0.75
B32: Treasury share purchases, CHF mm/year | F32: 5234 | G32: 4678 | H32: 213 | I32: =IF((H364+H375+H371-H341)/(H267+H288)>Input!$F$185,0,Input!I$141) -> 0 | J32: =IF((I364+I375+I371-I341)/(I267+I288)>Input!$F$185,0,Input!J$141) -> 0 | K32: =IF((J364+J375+J371-J341)/(J267+J288)>Input!$F$185,0,Input!K$141) -> 0 | L32: =IF((K364+K375+K371-K341)/(K267+K288)>Input!$F$185,0,Input!L$141) -> 0 | M32: =IF((L364+L375+L371-L341)/(L267+L288)>Input!$F$185,0,Input!M$141) -> 2000
B33: Dividends received from associates & JV, % of opening balance | G33: 0.057992054 | H33: 0.19223789 | I33: =Input!I$148 -> 0.065 | J33: =Input!J$148 -> 0.06 | K33: =Input!K$148 -> 0.06 | L33: =Input!L$148 -> 0.06 | M33: =Input!M$148 -> 0.06
B36: Working Capital Schedule
B38: =Input!$B$131 -> All figures in CHF millions unless stated | F38: =F$2 -> 2023 | G38: =G$2 -> 2024 | H38: =H$2 -> 2025 | I38: =I$2 -> 2026 | J38: =J$2 -> 2027 | K38: =K$2 -> 2028 | L38: =L$2 -> 2029 | M38: =M$2 -> 2030
B39: =CONCATENATE("Model Running: ",INDEX(Input!$B$12:$B$14,Input!$D$6)," Drivers") -> Model Running: Base Case Drivers
B41: Days in Period | F41: =Input!$F$174 -> 365 | G41: =Input!$F$174 -> 365 | H41: =Input!$F$174 -> 365 | I41: =Input!$F$174 -> 365 | J41: =Input!$F$174 -> 365 | K41: =Input!$F$174 -> 365 | L41: =Input!$F$174 -> 365 | M41: =Input!$F$174 -> 365
B42: Revenue | F42: =F255 -> 92998 | G42: =G255 -> 91354 | H42: =H255 -> 89490 | I42: =I255 -> 89937.45 | J42: =J255 -> 91286.512 | K42: =K255 -> 91742.944 | L42: =L255 -> 93577.803 | M42: =M255 -> 96197.982
B43: COGS | F43: =-F257 -> 50328 | G43: =-G257 -> 48670 | H43: =-H257 -> 48694 | I43: =-I257 -> 48738.04 | J43: =-J257 -> 49651.426 | K43: =-K257 -> 50533.633 | L43: =-L257 -> 51462.029 | M43: =-M257 -> 52775.864
B45: AMOUNTS PER DAY
B46: Accounts Receivable (Days) | F46: =(F53/F42)*F41 -> 43.153347 | G46: =(G53/G42)*G41 -> 44.952766 | H46: =(H53/H42)*H41 -> 43.074813 | I46: =Input!I86 -> 43 | J46: =Input!J86 -> 43 | K46: =Input!K86 -> 42.5 | L46: =Input!L86 -> 42 | M46: =Input!M86 -> 42
B47: Inventory (Days) | F47: =(F54/F43)*F41 -> 86.274837 | G47: =(G54/G43)*G41 -> 99.443189 | H47: =(H54/H43)*H41 -> 96.043558 | I47: =Input!I93 -> 93 | J47: =Input!J93 -> 91 | K47: =Input!K93 -> 89 | L47: =Input!L93 -> 88 | M47: =Input!M93 -> 87
B48: Accounts Payable (Days) | F48: =(F55/F43)*F41 -> 139.27555 | G48: =(G55/G43)*G41 -> 163.5413 | H48: =(H55/H43)*H41 -> 150.0882 | I48: =Input!I100 -> 150 | J48: =Input!J100 -> 150 | K48: =Input!K100 -> 150 | L48: =Input!L100 -> 150 | M48: =Input!M100 -> 150
B49: Prepayments (Days) | F49: =(F56/F42)*F41 -> 2.0448289 | G49: =(G56/G42)*G41 -> 2.1695273 | H49: =(H56/H42)*H41 -> 1.953682 | I49: =Input!I107 -> 2 | J49: =Input!J107 -> 2 | K49: =Input!K107 -> 2 | L49: =Input!L107 -> 2 | M49: =Input!M107 -> 2
B50: Accruals (Days) | F50: =(F57/F43)*F41 -> 37.074392 | G50: =(G57/G43)*G41 -> 40.992192 | H50: =(H57/H43)*H41 -> 41.789029 | I50: =Input!I108 -> 40 | J50: =Input!J108 -> 40 | K50: =Input!K108 -> 40 | L50: =Input!L108 -> 41 | M50: =Input!M108 -> 41
B52: TOTAL AMOUNTS
B53: Accounts Receivable | F53: 10995 | G53: 11251 | H53: 10561 | I53: =(I46/I41)*I42 -> 10595.371 | J53: =(J46/J41)*J42 -> 10754.301 | K53: =(K46/K41)*K42 -> 10682.398 | L53: =(L46/L41)*L42 -> 10767.857 | M53: =(M46/M41)*M42 -> 11069.357
B54: Inventory | F54: 11896 | G54: 13260 | H54: 12813 | I54: =(I47/I41)*I43 -> 12418.185 | J54: =(J47/J41)*J43 -> 12378.849 | K54: =(K47/K41)*K43 -> 12321.899 | L54: =(L47/L41)*L43 -> 12407.284 | M54: =(M47/M41)*M43 -> 12579.452
...
